Workbook

Sheet README
A1: Anaerobic Digester Sludge Recirculation – Mixing/Dilution-Only Theoretical Tracking (Draft)
A3: Purpose | B3: Track the 21-day sludge recirculation theoretically by mixing/dilution only (no microbial growth, no substrate consumption, no decay).
A4: Workbook scope | B4: 1) Chemistry: pH, Alk, TVFA, COD, VS 2) qPCR-like abundance: BAC, ARC 3) NGS composition: bacteria and archaea top taxa + Others.
A5: Key assumption | B5: Each reactor is treated as a daily mixed CSTR-style mass balance: C(t+1)=C(t)+dt/V*ΣQ(C_in-C).
A6: pH handling | B6: pH is estimated from conservative H+ mixing only. Interpret pH results cautiously; Alk/TVFA/VFA/Alk are the stronger theoretical outputs.
A7: How to use | B7: Fill yellow cells in Inputs / NGS input sheets with measured day-0 values and feed compositions. The rest of the workbook updates automatically.
A8: Suggested paper framing | B8: Use this workbook as a null model: 'How much recovery is explainable by sludge redistribution and dilution alone?'
A10: Color / Cell Logic
A11: Yellow fill + blue text | B11: User input / measured value to be overwritten
A12: Gray fill | B12: Static constant / label
A13: Black text | B13: Derived formula
A14: Orange fill | B14: Review / caution note
A16: Recommended workflow
A17: 1. Confirm R1–R5 working volumes and exact FWW flows in Inputs.
A18: 2. Paste day-0 reactor chemistry (d179 or chosen baseline) and BAC/ARC.
A19: 3. Paste stream chemistry for SS reservoir and FWW.
A20: 4. Paste NGS relative abundances (top taxa + Others auto-computes).
A21: 5. Review Reservoir, Chemistry_Daily, BAC_ARC_Daily, and NGS sheets.
A22: 6. Compare R4/R5 model outputs vs observed recovery in Observed_Compare.

Sheet Inputs
A1: Inputs and Operating Assumptions
A3: Global controls
A4: Operation days | B4: 21
A5: Time step dt (d) | B5: 1
A6: Active RS pool flow (m3/d) | B6: =D12*I12+D13*I13+D14*I14+D15*I15+D16*I16 -> 431.9
A7: pH theory note | B7: Conservative H+ mixing only (buffer chemistry not solved).
A8: Main null-model note | B8: No growth / no decay / no substrate conversion. Only hydraulic mixing and dilution.
A10: Reactor hydraulics (prefilled from your figure; confirm exact values)
A11: Reactor | B11: Working volume (m3) | C11: SS flow (m3/d) | D11: RS flow (m3/d) | E11: FWW flow (m3/d) | F11: Total in/out (m3/d) | G11: 21d cumulative RS (m3) | H11: Augmentation (% of V) | I11: Include in RS pool (1/0) | J11: Note
A12: R1 | B12: 3500 | C12: 58.5 | D12: 91.5 | E12: 30 | F12: =SUM(C12:E12) -> 180 | G12: =D12*$B$4 -> 1921.5 | H12: =IF(B12<>0,G12/B12,"") -> 0.549 | I12: 1 | J12: FWW prefilled from figure as 22 / 30 m3/d placeholder. Confirm exact split from operation log.
A13: R2 | B13: 3500 | C13: 58.5 | D13: 91.5 | E13: 30 | F13: =SUM(C13:E13) -> 180 | G13: =D13*$B$4 -> 1921.5 | H13: =IF(B13<>0,G13/B13,"") -> 0.549 | I13: 1 | J13: FWW prefilled from figure as 22 / 30 m3/d placeholder. Confirm exact split from operation log.
A14: R3 | B14: 3390 | C14: 42.1 | D14: 65.9 | E14: 40 | F14: =SUM(C14:E14) -> 148 | G14: =D14*$B$4 -> 1383.9 | H14: =IF(B14<>0,G14/B14,"") -> 0.40823009 | I14: 1 | J14: FWW prefilled from figure as 40 m3/d.
A15: R4 | B15: 3500 | C15: 58.5 | D15: 91.5 | E15: 0 | F15: =SUM(C15:E15) -> 150 | G15: =D15*$B$4 -> 1921.5 | H15: =IF(B15<>0,G15/B15,"") -> 0.549 | I15: 1 | J15: No FWW shown in figure.
A16: R5 | B16: 3500 | C16: 58.5 | D16: 91.5 | E16: 0 | F16: =SUM(C16:E16) -> 150 | G16: =D16*$B$4 -> 1921.5 | H16: =IF(B16<>0,G16/B16,"") -> 0.549 | I16: 1 | J16: No FWW shown in figure.
A21: Feed / source stream properties (enter measured or assumed values)
A22: Variable | B22: Unit | C22: SS reservoir | D22: FWW | E22: Note
A23: pH | B23: - | C23: 6.5 | D23: 3.9 | E23: Used only for conservative H+ mixing estimate.
A24: Alkalinity | B24: g/L as CaCO3 | C24: 1.1 | D24: 0 | E24: Conservative mixing only; no carbonate equilibrium recalculation.
A25: TVFA | B25: g/L | C25: 0.7 | D25: 13.1 | E25: Enter as acetate-equivalent or your standard TVFA basis.
A26: COD | B26: g/L | C26: 58.7 | D26: 96.7 | E26: Optional but useful for comparison with observed COD recovery.
A27: VS | B27: g/L | C27: 27.1 | D27: 60.4 | E27: Optional but useful for comparison with observed VS recovery.
A28: BAC | B28: copies/mL | C28: 35424.938 | D28: 0 | E28: qPCR-like bacterial abundance concentration.
A29: ARC | B29: copies/mL | C29: 4471689.8 | D29: 0 | E29: qPCR-like archaeal abundance concentration.
A33: Initial reactor state at day 0 (fill with measured pre-recirculation values)
A34: Reactor | B34: pH | C34: Alkalinity | D34: TVFA | E34: COD | F34: VS | G34: BAC | H34: ARC | I34: Note
A35: R1 | B35: 7.2 | C35: 3.5 | D35: 0.09 | E35: 25.6 | F35: 18.1 | G35: 974582.68 | H35: 17543034 | I35: Recommended: use d179 (or chosen day-0) reactor-specific measured values.
A36: R2 | B36: 7.2 | C36: 3.5 | D36: 0.091 | E36: 24.6 | F36: 17.9 | G36: 1954522.3 | H36: 16068873 | I36: Recommended: use d179 (or chosen day-0) reactor-specific measured values.
A37: R3 | B37: 7.2 | C37: 3.8 | D37: 0.0919 | E37: 24 | F37: 17.5 | G37: 1404076.4 | H37: 13068243 | I37: Recommended: use d179 (or chosen day-0) reactor-specific measured values.
A38: R4 | B38: 6.5 | C38: 0.713 | D38: 0.513 | E38: 40.5 | F38: 30.5 | G38: 967106.58 | H38: 7753954.5 | I38: Recommended: use d179 (or chosen day-0) reactor-specific measured values.
A39: R5 | B39: 6.5 | C39: 0.626 | D39: 0.433 | E39: 40.3 | F39: 30 | G39: 1462050.8 | H39: 7043007.9 | I39: Recommended: use d179 (or chosen day-0) reactor-specific measured values.
A42: Observed post-recovery values from your image (prefilled; editable)
A43: Reactor | B43: pH | C43: Alkalinity | D43: TVFA | E43: COD | F43: VS | G43: COD removal | H43: VS removal | I43: Carbohydrate removal | J43: Protein removal | K43: Lipid removal
A44: R4 | B44: 7.3 | C44: 3.7 | D44: 0.1 | E44: 24.3 | F44: 15.3 | G44: 0.481 | H44: 0.417 | I44: 0.481 | J44: 0.266 | K44: 0.701
A45: R5 | B45: 7.3 | C45: 3.7 | D45: 0.1 | E45: 24.7 | F45: 15.5 | G45: 0.469 | H45: 0.409 | I45: 0.489 | J45: 0.237 | K45: 0.692
A48: Optional observed BAC / ARC after recirculation
A49: Reactor | B49: BAC | C49: ARC | D49: Note
A50: R4 | B50: 8386991.9 | C50: 11536863 | D50: Fill if qPCR results are available.
A51: R5 | B51: 4889659.8 | C51: 10313851 | D51: Fill if qPCR results are available.

Sheet Reservoir
A1: Return Sludge Reservoir Composition (flow-weighted from reactor effluents)
A3: Daily RS pool composition
A4: Day | B4: H+ | C4: pH | D4: Alkalinity | E4: TVFA | F4: COD | G4: VS | H4: BAC | I4: ARC
A5: 0 | B5: =(Inputs!$D$12*Inputs!$I$12*Chemistry_Daily!B5+Inputs!$D$13*Inputs!$I$13*Chemistry_Daily!K5+Inputs!$D$14*Inputs!$I$14*Chemistry_Daily!T5+Inputs!$D$15*Inputs!$I$15*Chemistry_Daily!AC5+Inputs!$D$16*Inputs!$I$16*Chemistry_Daily!AL5)/(Inputs!$D$12*Inputs!$I$12+Inputs!$D$13*Inputs!$I$13+Inputs!$D$14*Inputs!$I$14+Inputs!$D$15*Inputs!$I$15+Inputs!$D$16*Inputs!$I$16) -> 1.703501e-07 | C5: =IF(B5>0,-LOG10(B5),"") -> 6.7686576 | D5: =(Inputs!$D$12*Inputs!$I$12*Chemistry_Daily!D5+Inputs!$D$13*Inputs!$I$13*Chemistry_Daily!M5+Inputs!$D$14*Inputs!$I$14*Chemistry_Daily!V5+Inputs!$D$15*Inputs!$I$15*Chemistry_Daily!AE5+Inputs!$D$16*Inputs!$I$16*Chemistry_Daily!AN5)/(Inputs!$D$12*Inputs!$I$12+Inputs!$D$13*Inputs!$I$13+Inputs!$D$14*Inputs!$I$14+Inputs!$D$15*Inputs!$I$15+Inputs!$D$16*Inputs!$I$16) -> 2.3464656 | E5: =(Inputs!$D$12*Inputs!$I$12*Chemistry_Daily!E5+Inputs!$D$13*Inputs!$I$13*Chemistry_Daily!N5+Inputs!$D$14*Inputs!$I$14*Chemistry_Daily!W5+Inputs!$D$15*Inputs!$I$15*Chemistry_Daily!AF5+Inputs!$D$16*Inputs!$I$16*Chemistry_Daily!AO5)/(Inputs!$D$12*Inputs!$I$12+Inputs!$D$13*Inputs!$I$13+Inputs!$D$14*Inputs!$I$14+Inputs!$D$15*Inputs!$I$15+Inputs!$D$16*Inputs!$I$16) -> 0.25278238 | F5: =(Inputs!$D$12*Inputs!$I$12*Chemistry_Daily!F5+Inputs!$D$13*Inputs!$I$13*Chemistry_Daily!O5+Inputs!$D$14*Inputs!$I$14*Chemistry_Daily!X5+Inputs!$D$15*Inputs!$I$15*Chemistry_Daily!AG5+Inputs!$D$16*Inputs!$I$16*Chemistry_Daily!AP5)/(Inputs!$D$12*Inputs!$I$12+Inputs!$D$13*Inputs!$I$13+Inputs!$D$14*Inputs!$I$14+Inputs!$D$15*Inputs!$I$15+Inputs!$D$16*Inputs!$I$16) -> 31.414911 | G5: =(Inputs!$D$12*Inputs!$I$12*Chemistry_Daily!G5+Inputs!$D$13*Inputs!$I$13*Chemistry_Daily!P5+Inputs!$D$14*Inputs!$I$14*Chemistry_Daily!Y5+Inputs!$D$15*Inputs!$I$15*Chemistry_Daily!AH5+Inputs!$D$16*Inputs!$I$16*Chemistry_Daily!AQ5)/(Inputs!$D$12*Inputs!$I$12+Inputs!$D$13*Inputs!$I$13+Inputs!$D$14*Inputs!$I$14+Inputs!$D$15*Inputs!$I$15+Inputs!$D$16*Inputs!$I$16) -> 23.114147 | H5: =(Inputs!$D$12*Inputs!$I$12*BAC_ARC_Daily!B5+Inputs!$D$13*Inputs!$I$13*BAC_ARC_Daily!I5+Inputs!$D$14*Inputs!$I$14*BAC_ARC_Daily!P5+Inputs!$D$15*Inputs!$I$15*BAC_ARC_Daily!W5+Inputs!$D$16*Inputs!$I$16*BAC_ARC_Daily!AD5)/(Inputs!$D$12*Inputs!$I$12+Inputs!$D$13*Inputs!$I$13+Inputs!$D$14*Inputs!$I$14+Inputs!$D$15*Inputs!$I$15+Inputs!$D$16*Inputs!$I$16) -> 1349408.7 | I5: =(Inputs!$D$12*Inputs!$I$12*BAC_ARC_Daily!C5+Inputs!$D$13*Inputs!$I$13*BAC_ARC_Daily!J5+Inputs!$D$14*Inputs!$I$14*BAC_ARC_Daily!Q5+Inputs!$D$15*Inputs!$I$15*BAC_ARC_Daily!X5+Inputs!$D$16*Inputs!$I$16*BAC_ARC_Daily!AE5)/(Inputs!$D$12*Inputs!$I$12+Inputs!$D$13*Inputs!$I$13+Inputs!$D$14*Inputs!$I$14+Inputs!$D$15*Inputs!$I$15+Inputs!$D$16*Inputs!$I$16) -> 12249615
A6: 1 | B6: =(Inputs!$D$12*Inputs!$I$12*Chemistry_Daily!B6+Inputs!$D$13*Inputs!$I$13*Chemistry_Daily!K6+Inputs!$D$14*Inputs!$I$14*Chemistry_Daily!T6+Inputs!$D$15*Inputs!$I$15*Chemistry_Daily!AC6+Inputs!$D$16*Inputs!$I$16*Chemistry_Daily!AL6)/(Inputs!$D$12*Inputs!$I$12+Inputs!$D$13*Inputs!$I$13+Inputs!$D$14*Inputs!$I$14+Inputs!$D$15*Inputs!$I$15+Inputs!$D$16*Inputs!$I$16) -> 8.5603919e-07 | C6: =IF(B6>0,-LOG10(B6),"") -> 6.0675064 | D6: =(Inputs!$D$12*Inputs!$I$12*Chemistry_Daily!D6+Inputs!$D$13*Inputs!$I$13*Chemistry_Daily!M6+Inputs!$D$14*Inputs!$I$14*Chemistry_Daily!V6+Inputs!$D$15*Inputs!$I$15*Chemistry_Daily!AE6+Inputs!$D$16*Inputs!$I$16*Chemistry_Daily!AN6)/(Inputs!$D$12*Inputs!$I$12+Inputs!$D$13*Inputs!$I$13+Inputs!$D$14*Inputs!$I$14+Inputs!$D$15*Inputs!$I$15+Inputs!$D$16*Inputs!$I$16) -> 2.3093354 | E6: =(Inputs!$D$12*Inputs!$I$12*Chemistry_Daily!E6+Inputs!$D$13*Inputs!$I$13*Chemistry_Daily!N6+Inputs!$D$14*Inputs!$I$14*Chemistry_Daily!W6+Inputs!$D$15*Inputs!$I$15*Chemistry_Daily!AF6+Inputs!$D$16*Inputs!$I$16*Chemistry_Daily!AO6)/(Inputs!$D$12*Inputs!$I$12+Inputs!$D$13*Inputs!$I$13+Inputs!$D$14*Inputs!$I$14+Inputs!$D$15*Inputs!$I$15+Inputs!$D$16*Inputs!$I$16) -> 0.33036145 | F6: =(Inputs!$D$12*Inputs!$I$12*Chemistry_Daily!F6+Inputs!$D$13*Inputs!$I$13*Chemistry_Daily!O6+Inputs!$D$14*Inputs!$I$14*Chemistry_Daily!X6+Inputs!$D$15*Inputs!$I$15*Chemistry_Daily!AG6+Inputs!$D$16*Inputs!$I$16*Chemistry_Daily!AP6)/(Inputs!$D$12*Inputs!$I$12+Inputs!$D$13*Inputs!$I$13+Inputs!$D$14*Inputs!$I$14+Inputs!$D$15*Inputs!$I$15+Inputs!$D$16*Inputs!$I$16) -> 32.231559 | G6: =(Inputs!$D$12*Inputs!$I$12*Chemistry_Daily!G6+Inputs!$D$13*Inputs!$I$13*Chemistry_Daily!P6+Inputs!$D$14*Inputs!$I$14*Chemistry_Daily!Y6+Inputs!$D$15*Inputs!$I$15*Chemistry_Daily!AH6+Inputs!$D$16*Inputs!$I$16*Chemistry_Daily!AQ6)/(Inputs!$D$12*Inputs!$I$12+Inputs!$D$13*Inputs!$I$13+Inputs!$D$14*Inputs!$I$14+Inputs!$D$15*Inputs!$I$15+Inputs!$D$16*Inputs!$I$16) -> 23.399957 | H6: =(Inputs!$D$12*Inputs!$I$12*BAC_ARC_Daily!B6+Inputs!$D$13*Inputs!$I$13*BAC_ARC_Daily!I6+Inputs!$D$14*Inputs!$I$14*BAC_ARC_Daily!P6+Inputs!$D$15*Inputs!$I$15*BAC_ARC_Daily!W6+Inputs!$D$16*Inputs!$I$16*BAC_ARC_Daily!AD6)/(Inputs!$D$12*Inputs!$I$12+Inputs!$D$13*Inputs!$I$13+Inputs!$D$14*Inputs!$I$14+Inputs!$D$15*Inputs!$I$15+Inputs!$D$16*Inputs!$I$16) -> 1320552.6 | I6: =(Inputs!$D$12*Inputs!$I$12*BAC_ARC_Daily!C6+Inputs!$D$13*Inputs!$I$13*BAC_ARC_Daily!J6+Inputs!$D$14*Inputs!$I$14*BAC_ARC_Daily!Q6+Inputs!$D$15*Inputs!$I$15*BAC_ARC_Daily!X6+Inputs!$D$16*Inputs!$I$16*BAC_ARC_Daily!AE6)/(Inputs!$D$12*Inputs!$I$12+Inputs!$D$13*Inputs!$I$13+Inputs!$D$14*Inputs!$I$14+Inputs!$D$15*Inputs!$I$15+Inputs!$D$16*Inputs!$I$16) -> 12041521
A7: 2 | B7: =(Inputs!$D$12*Inputs!$I$12*Chemistry_Daily!B7+Inputs!$D$13*Inputs!$I$13*Chemistry_Daily!K7+Inputs!$D$14*Inputs!$I$14*Chemistry_Daily!T7+Inputs!$D$15*Inputs!$I$15*Chemistry_Daily!AC7+Inputs!$D$16*Inputs!$I$16*Chemistry_Daily!AL7)/(Inputs!$D$12*Inputs!$I$12+Inputs!$D$13*Inputs!$I$13+Inputs!$D$14*Inputs!$I$14+Inputs!$D$15*Inputs!$I$15+Inputs!$D$16*Inputs!$I$16) -> 1.5254416e-06 | C7: =IF(B7>0,-LOG10(B7),"") -> 5.8166044 | D7: =(Inputs!$D$12*Inputs!$I$12*Chemistry_Daily!D7+Inputs!$D$13*Inputs!$I$13*Chemistry_Daily!M7+Inputs!$D$14*Inputs!$I$14*Chemistry_Daily!V7+Inputs!$D$15*Inputs!$I$15*Chemistry_Daily!AE7+Inputs!$D$16*Inputs!$I$16*Chemistry_Daily!AN7)/(Inputs!$D$12*Inputs!$I$12+Inputs!$D$13*Inputs!$I$13+Inputs!$D$14*Inputs!$I$14+Inputs!$D$15*Inputs!$I$15+Inputs!$D$16*Inputs!$I$16) -> 2.273241 | E7: =(Inputs!$D$12*Inputs!$I$12*Chemistry_Daily!E7+Inputs!$D$13*Inputs!$I$13*Chemistry_Daily!N7+Inputs!$D$14*Inputs!$I$14*Chemistry_Daily!W7+Inputs!$D$15*Inputs!$I$15*Chemistry_Daily!AF7+Inputs!$D$16*Inputs!$I$16*Chemistry_Daily!AO7)/(Inputs!$D$12*Inputs!$I$12+Inputs!$D$13*Inputs!$I$13+Inputs!$D$14*Inputs!$I$14+Inputs!$D$15*Inputs!$I$15+Inputs!$D$16*Inputs!$I$16) -> 0.40608705 | F7: =(Inputs!$D$12*Inputs!$I$12*Chemistry_Daily!F7+Inputs!$D$13*Inputs!$I$13*Chemistry_Daily!O7+Inputs!$D$14*Inputs!$I$14*Chemistry_Daily!X7+Inputs!$D$15*Inputs!$I$15*Chemistry_Daily!AG7+Inputs!$D$16*Inputs!$I$16*Chemistry_Daily!AP7)/(Inputs!$D$12*Inputs!$I$12+Inputs!$D$13*Inputs!$I$13+Inputs!$D$14*Inputs!$I$14+Inputs!$D$15*Inputs!$I$15+Inputs!$D$16*Inputs!$I$16) -> 33.028679 | G7: =(Inputs!$D$12*Inputs!$I$12*Chemistry_Daily!G7+Inputs!$D$13*Inputs!$I$13*Chemistry_Daily!P7+Inputs!$D$14*Inputs!$I$14*Chemistry_Daily!Y7+Inputs!$D$15*Inputs!$I$15*Chemistry_Daily!AH7+Inputs!$D$16*Inputs!$I$16*Chemistry_Daily!AQ7)/(Inputs!$D$12*Inputs!$I$12+Inputs!$D$13*Inputs!$I$13+Inputs!$D$14*Inputs!$I$14+Inputs!$D$15*Inputs!$I$15+Inputs!$D$16*Inputs!$I$16) -> 23.678251 | H7: =(Inputs!$D$12*Inputs!$I$12*BAC_ARC_Daily!B7+Inputs!$D$13*Inputs!$I$13*BAC_ARC_Daily!I7+Inputs!$D$14*Inputs!$I$14*BAC_ARC_Daily!P7+Inputs!$D$15*Inputs!$I$15*BAC_ARC_Daily!W7+Inputs!$D$16*Inputs!$I$16*BAC_ARC_Daily!AD7)/(Inputs!$D$12*Inputs!$I$12+Inputs!$D$13*Inputs!$I$13+Inputs!$D$14*Inputs!$I$14+Inputs!$D$15*Inputs!$I$15+Inputs!$D$16*Inputs!$I$16) -> 1292355.7 | I7: =(Inputs!$D$12*Inputs!$I$12*BAC_ARC_Daily!C7+Inputs!$D$13*Inputs!$I$13*BAC_ARC_Daily!J7+Inputs!$D$14*Inputs!$I$14*BAC_ARC_Daily!Q7+Inputs!$D$15*Inputs!$I$15*BAC_ARC_Daily!X7+Inputs!$D$16*Inputs!$I$16*BAC_ARC_Daily!AE7)/(Inputs!$D$12*Inputs!$I$12+Inputs!$D$13*Inputs!$I$13+Inputs!$D$14*Inputs!$I$14+Inputs!$D$15*Inputs!$I$15+Inputs!$D$16*Inputs!$I$16) -> 11838855
A8: 3 | B8: =(Inputs!$D$12*Inputs!$I$12*Chemistry_Daily!B8+Inputs!$D$13*Inputs!$I$13*Chemistry_Daily!K8+Inputs!$D$14*Inputs!$I$14*Chemistry_Daily!T8+Inputs!$D$15*Inputs!$I$15*Chemistry_Daily!AC8+Inputs!$D$16*Inputs!$I$16*Chemistry_Daily!AL8)/(Inputs!$D$12*Inputs!$I$12+Inputs!$D$13*Inputs!$I$13+Inputs!$D$14*Inputs!$I$14+Inputs!$D$15*Inputs!$I$15+Inputs!$D$16*Inputs!$I$16) -> 2.17899e-06 | C8: =IF(B8>0,-LOG10(B8),"") -> 5.6617448 | D8: =(Inputs!$D$12*Inputs!$I$12*Chemistry_Daily!D8+Inputs!$D$13*Inputs!$I$13*Chemistry_Daily!M8+Inputs!$D$14*Inputs!$I$14*Chemistry_Daily!V8+Inputs!$D$15*Inputs!$I$15*Chemistry_Daily!AE8+Inputs!$D$16*Inputs!$I$16*Chemistry_Daily!AN8)/(Inputs!$D$12*Inputs!$I$12+Inputs!$D$13*Inputs!$I$13+Inputs!$D$14*Inputs!$I$14+Inputs!$D$15*Inputs!$I$15+Inputs!$D$16*Inputs!$I$16) -> 2.2381482 | E8: =(Inputs!$D$12*Inputs!$I$12*Chemistry_Daily!E8+Inputs!$D$13*Inputs!$I$13*Chemistry_Daily!N8+Inputs!$D$14*Inputs!$I$14*Chemistry_Daily!W8+Inputs!$D$15*Inputs!$I$15*Chemistry_Daily!AF8+Inputs!$D$16*Inputs!$I$16*Chemistry_Daily!AO8)/(Inputs!$D$12*Inputs!$I$12+Inputs!$D$13*Inputs!$I$13+Inputs!$D$14*Inputs!$I$14+Inputs!$D$15*Inputs!$I$15+Inputs!$D$16*Inputs!$I$16) -> 0.4800089 | F8: =(Inputs!$D$12*Inputs!$I$12*Chemistry_Daily!F8+Inputs!$D$13*Inputs!$I$13*Chemistry_Daily!O8+Inputs!$D$14*Inputs!$I$14*Chemistry_Daily!X8+Inputs!$D$15*Inputs!$I$15*Chemistry_Daily!AG8+Inputs!$D$16*Inputs!$I$16*Chemistry_Daily!AP8)/(Inputs!$D$12*Inputs!$I$12+Inputs!$D$13*Inputs!$I$13+Inputs!$D$14*Inputs!$I$14+Inputs!$D$15*Inputs!$I$15+Inputs!$D$16*Inputs!$I$16) -> 33.806795 | G8: =(Inputs!$D$12*Inputs!$I$12*Chemistry_Daily!G8+Inputs!$D$13*Inputs!$I$13*Chemistry_Daily!P8+Inputs!$D$14*Inputs!$I$14*Chemistry_Daily!Y8+Inputs!$D$15*Inputs!$I$15*Chemistry_Daily!AH8+Inputs!$D$16*Inputs!$I$16*Chemistry_Daily!AQ8)/(Inputs!$D$12*Inputs!$I$12+Inputs!$D$13*Inputs!$I$13+Inputs!$D$14*Inputs!$I$14+Inputs!$D$15*Inputs!$I$15+Inputs!$D$16*Inputs!$I$16) -> 23.949258 | H8: =(Inputs!$D$12*Inputs!$I$12*BAC_ARC_Daily!B8+Inputs!$D$13*Inputs!$I$13*BAC_ARC_Daily!I8+Inputs!$D$14*Inputs!$I$14*BAC_ARC_Daily!P8+Inputs!$D$15*Inputs!$I$15*BAC_ARC_Daily!W8+Inputs!$D$16*Inputs!$I$16*BAC_ARC_Daily!AD8)/(Inputs!$D$12*Inputs!$I$12+Inputs!$D$13*Inputs!$I$13+Inputs!$D$14*Inputs!$I$14+Inputs!$D$15*Inputs!$I$15+Inputs!$D$16*Inputs!$I$16) -> 1264801.7 | I8: =(Inputs!$D$12*Inputs!$I$12*BAC_ARC_Daily!C8+Inputs!$D$13*Inputs!$I$13*BAC_ARC_Daily!J8+Inputs!$D$14*Inputs!$I$14*BAC_ARC_Daily!Q8+Inputs!$D$15*Inputs!$I$15*BAC_ARC_Daily!X8+Inputs!$D$16*Inputs!$I$16*BAC_ARC_Daily!AE8)/(Inputs!$D$12*Inputs!$I$12+Inputs!$D$13*Inputs!$I$13+Inputs!$D$14*Inputs!$I$14+Inputs!$D$15*Inputs!$I$15+Inputs!$D$16*Inputs!$I$16) -> 11641454
A9: 4 | B9: =(Inputs!$D$12*Inputs!$I$12*Chemistry_Daily!B9+Inputs!$D$13*Inputs!$I$13*Chemistry_Daily!K9+Inputs!$D$14*Inputs!$I$14*Chemistry_Daily!T9+Inputs!$D$15*Inputs!$I$15*Chemistry_Daily!AC9+Inputs!$D$16*Inputs!$I$16*Chemistry_Daily!AL9)/(Inputs!$D$12*Inputs!$I$12+Inputs!$D$13*Inputs!$I$13+Inputs!$D$14*Inputs!$I$14+Inputs!$D$15*Inputs!$I$15+Inputs!$D$16*Inputs!$I$16) -> 2.8171041e-06 | C9: =IF(B9>0,-LOG10(B9),"") -> 5.5501971 | D9: =(Inputs!$D$12*Inputs!$I$12*Chemistry_Daily!D9+Inputs!$D$13*Inputs!$I$13*Chemistry_Daily!M9+Inputs!$D$14*Inputs!$I$14*Chemistry_Daily!V9+Inputs!$D$15*Inputs!$I$15*Chemistry_Daily!AE9+Inputs!$D$16*Inputs!$I$16*Chemistry_Daily!AN9)/(Inputs!$D$12*Inputs!$I$12+Inputs!$D$13*Inputs!$I$13+Inputs!$D$14*Inputs!$I$14+Inputs!$D$15*Inputs!$I$15+Inputs!$D$16*Inputs!$I$16) -> 2.2040245 | E9: =(Inputs!$D$12*Inputs!$I$12*Chemistry_Daily!E9+Inputs!$D$13*Inputs!$I$13*Chemistry_Daily!N9+Inputs!$D$14*Inputs!$I$14*Chemistry_Daily!W9+Inputs!$D$15*Inputs!$I$15*Chemistry_Daily!AF9+Inputs!$D$16*Inputs!$I$16*Chemistry_Daily!AO9)/(Inputs!$D$12*Inputs!$I$12+Inputs!$D$13*Inputs!$I$13+Inputs!$D$14*Inputs!$I$14+Inputs!$D$15*Inputs!$I$15+Inputs!$D$16*Inputs!$I$16) -> 0.55217516 | F9: =(Inputs!$D$12*Inputs!$I$12*Chemistry_Daily!F9+Inputs!$D$13*Inputs!$I$13*Chemistry_Daily!O9+Inputs!$D$14*Inputs!$I$14*Chemistry_Daily!X9+Inputs!$D$15*Inputs!$I$15*Chemistry_Daily!AG9+Inputs!$D$16*Inputs!$I$16*Chemistry_Daily!AP9)/(Inputs!$D$12*Inputs!$I$12+Inputs!$D$13*Inputs!$I$13+Inputs!$D$14*Inputs!$I$14+Inputs!$D$15*Inputs!$I$15+Inputs!$D$16*Inputs!$I$16) -> 34.566417 | G9: =(Inputs!$D$12*Inputs!$I$12*Chemistry_Daily!G9+Inputs!$D$13*Inputs!$I$13*Chemistry_Daily!P9+Inputs!$D$14*Inputs!$I$14*Chemistry_Daily!Y9+Inputs!$D$15*Inputs!$I$15*Chemistry_Daily!AH9+Inputs!$D$16*Inputs!$I$16*Chemistry_Daily!AQ9)/(Inputs!$D$12*Inputs!$I$12+Inputs!$D$13*Inputs!$I$13+Inputs!$D$14*Inputs!$I$14+Inputs!$D$15*Inputs!$I$15+Inputs!$D$16*Inputs!$I$16) -> 24.213202 | H9: =(Inputs!$D$12*Inputs!$I$12*BAC_ARC_Daily!B9+Inputs!$D$13*Inputs!$I$13*BAC_ARC_Daily!I9+Inputs!$D$14*Inputs!$I$14*BAC_ARC_Daily!P9+Inputs!$D$15*Inputs!$I$15*BAC_ARC_Daily!W9+Inputs!$D$16*Inputs!$I$16*BAC_ARC_Daily!AD9)/(Inputs!$D$12*Inputs!$I$12+Inputs!$D$13*Inputs!$I$13+Inputs!$D$14*Inputs!$I$14+Inputs!$D$15*Inputs!$I$15+Inputs!$D$16*Inputs!$I$16) -> 1237874.7 | I9: =(Inputs!$D$12*Inputs!$I$12*BAC_ARC_Daily!C9+Inputs!$D$13*Inputs!$I$13*BAC_ARC_Daily!J9+Inputs!$D$14*Inputs!$I$14*BAC_ARC_Daily!Q9+Inputs!$D$15*Inputs!$I$15*BAC_ARC_Daily!X9+Inputs!$D$16*Inputs!$I$16*BAC_ARC_Daily!AE9)/(Inputs!$D$12*Inputs!$I$12+Inputs!$D$13*Inputs!$I$13+Inputs!$D$14*Inputs!$I$14+Inputs!$D$15*Inputs!$I$15+Inputs!$D$16*Inputs!$I$16) -> 11449158
A10: 5 | B10: =(Inputs!$D$12*Inputs!$I$12*Chemistry_Daily!B10+Inputs!$D$13*Inputs!$I$13*Chemistry_Daily!K10+Inputs!$D$14*Inputs!$I$14*Chemistry_Daily!T10+Inputs!$D$15*Inputs!$I$15*Chemistry_Daily!AC10+Inputs!$D$16*Inputs!$I$16*Chemistry_Daily!AL10)/(Inputs!$D$12*Inputs!$I$12+Inputs!$D$13*Inputs!$I$13+Inputs!$D$14*Inputs!$I$14+Inputs!$D$15*Inputs!$I$15+Inputs!$D$16*Inputs!$I$16) -> 3.4401901e-06 | C10: =IF(B10>0,-LOG10(B10),"") -> 5.4634176 | D10: =(Inputs!$D$12*Inputs!$I$12*Chemistry_Daily!D10+Inputs!$D$13*Inputs!$I$13*Chemistry_Daily!M10+Inputs!$D$14*Inputs!$I$14*Chemistry_Daily!V10+Inputs!$D$15*Inputs!$I$15*Chemistry_Daily!AE10+Inputs!$D$16*Inputs!$I$16*Chemistry_Daily!AN10)/(Inputs!$D$12*Inputs!$I$12+Inputs!$D$13*Inputs!$I$13+Inputs!$D$14*Inputs!$I$14+Inputs!$D$15*Inputs!$I$15+Inputs!$D$16*Inputs!$I$16) -> 2.1708382 | E10: =(Inputs!$D$12*Inputs!$I$12*Chemistry_Daily!E10+Inputs!$D$13*Inputs!$I$13*Chemistry_Daily!N10+Inputs!$D$14*Inputs!$I$14*Chemistry_Daily!W10+Inputs!$D$15*Inputs!$I$15*Chemistry_Daily!AF10+Inputs!$D$16*Inputs!$I$16*Chemistry_Daily!AO10)/(Inputs!$D$12*Inputs!$I$12+Inputs!$D$13*Inputs!$I$13+Inputs!$D$14*Inputs!$I$14+Inputs!$D$15*Inputs!$I$15+Inputs!$D$16*Inputs!$I$16) -> 0.62263249 | F10: =(Inputs!$D$12*Inputs!$I$12*Chemistry_Daily!F10+Inputs!$D$13*Inputs!$I$13*Chemistry_Daily!O10+Inputs!$D$14*Inputs!$I$14*Chemistry_Daily!X10+Inputs!$D$15*Inputs!$I$15*Chemistry_Daily!AG10+Inputs!$D$16*Inputs!$I$16*Chemistry_Daily!AP10)/(Inputs!$D$12*Inputs!$I$12+Inputs!$D$13*Inputs!$I$13+Inputs!$D$14*Inputs!$I$14+Inputs!$D$15*Inputs!$I$15+Inputs!$D$16*Inputs!$I$16) -> 35.308036 | G10: =(Inputs!$D$12*Inputs!$I$12*Chemistry_Daily!G10+Inputs!$D$13*Inputs!$I$13*Chemistry_Daily!P10+Inputs!$D$14*Inputs!$I$14*Chemistry_Daily!Y10+Inputs!$D$15*Inputs!$I$15*Chemistry_Daily!AH10+Inputs!$D$16*Inputs!$I$16*Chemistry_Daily!AQ10)/(Inputs!$D$12*Inputs!$I$12+Inputs!$D$13*Inputs!$I$13+Inputs!$D$14*Inputs!$I$14+Inputs!$D$15*Inputs!$I$15+Inputs!$D$16*Inputs!$I$16) -> 24.470295 | H10: =(Inputs!$D$12*Inputs!$I$12*BAC_ARC_Daily!B10+Inputs!$D$13*Inputs!$I$13*BAC_ARC_Daily!I10+Inputs!$D$14*Inputs!$I$14*BAC_ARC_Daily!P10+Inputs!$D$15*Inputs!$I$15*BAC_ARC_Daily!W10+Inputs!$D$16*Inputs!$I$16*BAC_ARC_Daily!AD10)/(Inputs!$D$12*Inputs!$I$12+Inputs!$D$13*Inputs!$I$13+Inputs!$D$14*Inputs!$I$14+Inputs!$D$15*Inputs!$I$15+Inputs!$D$16*Inputs!$I$16) -> 1211559.1 | I10: =(Inputs!$D$12*Inputs!$I$12*BAC_ARC_Daily!C10+Inputs!$D$13*Inputs!$I$13*BAC_ARC_Daily!J10+Inputs!$D$14*Inputs!$I$14*BAC_ARC_Daily!Q10+Inputs!$D$15*Inputs!$I$15*BAC_ARC_Daily!X10+Inputs!$D$16*Inputs!$I$16*BAC_ARC_Daily!AE10)/(Inputs!$D$12*Inputs!$I$12+Inputs!$D$13*Inputs!$I$13+Inputs!$D$14*Inputs!$I$14+Inputs!$D$15*Inputs!$I$15+Inputs!$D$16*Inputs!$I$16) -> 11261813
A11: 6 | B11: =(Inputs!$D$12*Inputs!$I$12*Chemistry_Daily!B11+Inputs!$D$13*Inputs!$I$13*Chemistry_Daily!K11+Inputs!$D$14*Inputs!$I$14*Chemistry_Daily!T11+Inputs!$D$15*Inputs!$I$15*Chemistry_Daily!AC11+Inputs!$D$16*Inputs!$I$16*Chemistry_Daily!AL11)/(Inputs!$D$12*Inputs!$I$12+Inputs!$D$13*Inputs!$I$13+Inputs!$D$14*Inputs!$I$14+Inputs!$D$15*Inputs!$I$15+Inputs!$D$16*Inputs!$I$16) -> 4.048642e-06 | C11: =IF(B11>0,-LOG10(B11),"") -> 5.3926906 | D11: =(Inputs!$D$12*Inputs!$I$12*Chemistry_Daily!D11+Inputs!$D$13*Inputs!$I$13*Chemistry_Daily!M11+Inputs!$D$14*Inputs!$I$14*Chemistry_Daily!V11+Inputs!$D$15*Inputs!$I$15*Chemistry_Daily!AE11+Inputs!$D$16*Inputs!$I$16*Chemistry_Daily!AN11)/(Inputs!$D$12*Inputs!$I$12+Inputs!$D$13*Inputs!$I$13+Inputs!$D$14*Inputs!$I$14+Inputs!$D$15*Inputs!$I$15+Inputs!$D$16*Inputs!$I$16) -> 2.1385591 | E11: =(Inputs!$D$12*Inputs!$I$12*Chemistry_Daily!E11+Inputs!$D$13*Inputs!$I$13*Chemistry_Daily!N11+Inputs!$D$14*Inputs!$I$14*Chemistry_Daily!W11+Inputs!$D$15*Inputs!$I$15*Chemistry_Daily!AF11+Inputs!$D$16*Inputs!$I$16*Chemistry_Daily!AO11)/(Inputs!$D$12*Inputs!$I$12+Inputs!$D$13*Inputs!$I$13+Inputs!$D$14*Inputs!$I$14+Inputs!$D$15*Inputs!$I$15+Inputs!$D$16*Inputs!$I$16) -> 0.6914261 | F11: =(Inputs!$D$12*Inputs!$I$12*Chemistry_Daily!F11+Inputs!$D$13*Inputs!$I$13*Chemistry_Daily!O11+Inputs!$D$14*Inputs!$I$14*Chemistry_Daily!X11+Inputs!$D$15*Inputs!$I$15*Chemistry_Daily!AG11+Inputs!$D$16*Inputs!$I$16*Chemistry_Daily!AP11)/(Inputs!$D$12*Inputs!$I$12+Inputs!$D$13*Inputs!$I$13+Inputs!$D$14*Inputs!$I$14+Inputs!$D$15*Inputs!$I$15+Inputs!$D$16*Inputs!$I$16) -> 36.03213 | G11: =(Inputs!$D$12*Inputs!$I$12*Chemistry_Daily!G11+Inputs!$D$13*Inputs!$I$13*Chemistry_Daily!P11+Inputs!$D$14*Inputs!$I$14*Chemistry_Daily!Y11+Inputs!$D$15*Inputs!$I$15*Chemistry_Daily!AH11+Inputs!$D$16*Inputs!$I$16*Chemistry_Daily!AQ11)/(Inputs!$D$12*Inputs!$I$12+Inputs!$D$13*Inputs!$I$13+Inputs!$D$14*Inputs!$I$14+Inputs!$D$15*Inputs!$I$15+Inputs!$D$16*Inputs!$I$16) -> 24.720746 | H11: =(Inputs!$D$12*Inputs!$I$12*BAC_ARC_Daily!B11+Inputs!$D$13*Inputs!$I$13*BAC_ARC_Daily!I11+Inputs!$D$14*Inputs!$I$14*BAC_ARC_Daily!P11+Inputs!$D$15*Inputs!$I$15*BAC_ARC_Daily!W11+Inputs!$D$16*Inputs!$I$16*BAC_ARC_Daily!AD11)/(Inputs!$D$12*Inputs!$I$12+Inputs!$D$13*Inputs!$I$13+Inputs!$D$14*Inputs!$I$14+Inputs!$D$15*Inputs!$I$15+Inputs!$D$16*Inputs!$I$16) -> 1185839.8 | I11: =(Inputs!$D$12*Inputs!$I$12*BAC_ARC_Daily!C11+Inputs!$D$13*Inputs!$I$13*BAC_ARC_Daily!J11+Inputs!$D$14*Inputs!$I$14*BAC_ARC_Daily!Q11+Inputs!$D$15*Inputs!$I$15*BAC_ARC_Daily!X11+Inputs!$D$16*Inputs!$I$16*BAC_ARC_Daily!AE11)/(Inputs!$D$12*Inputs!$I$12+Inputs!$D$13*Inputs!$I$13+Inputs!$D$14*Inputs!$I$14+Inputs!$D$15*Inputs!$I$15+Inputs!$D$16*Inputs!$I$16) -> 11079272
A12: 7 | B12: =(Inputs!$D$12*Inputs!$I$12*Chemistry_Daily!B12+Inputs!$D$13*Inputs!$I$13*Chemistry_Daily!K12+Inputs!$D$14*Inputs!$I$14*Chemistry_Daily!T12+Inputs!$D$15*Inputs!$I$15*Chemistry_Daily!AC12+Inputs!$D$16*Inputs!$I$16*Chemistry_Daily!AL12)/(Inputs!$D$12*Inputs!$I$12+Inputs!$D$13*Inputs!$I$13+Inputs!$D$14*Inputs!$I$14+Inputs!$D$15*Inputs!$I$15+Inputs!$D$16*Inputs!$I$16) -> 4.6428419e-06 | C12: =IF(B12>0,-LOG10(B12),"") -> 5.3332161 | D12: =(Inputs!$D$12*Inputs!$I$12*Chemistry_Daily!D12+Inputs!$D$13*Inputs!$I$13*Chemistry_Daily!M12+Inputs!$D$14*Inputs!$I$14*Chemistry_Daily!V12+Inputs!$D$15*Inputs!$I$15*Chemistry_Daily!AE12+Inputs!$D$16*Inputs!$I$16*Chemistry_Daily!AN12)/(Inputs!$D$12*Inputs!$I$12+Inputs!$D$13*Inputs!$I$13+Inputs!$D$14*Inputs!$I$14+Inputs!$D$15*Inputs!$I$15+Inputs!$D$16*Inputs!$I$16) -> 2.107158 | E12: =(Inputs!$D$12*Inputs!$I$12*Chemistry_Daily!E12+Inputs!$D$13*Inputs!$I$13*Chemistry_Daily!N12+Inputs!$D$14*Inputs!$I$14*Chemistry_Daily!W12+Inputs!$D$15*Inputs!$I$15*Chemistry_Daily!AF12+Inputs!$D$16*Inputs!$I$16*Chemistry_Daily!AO12)/(Inputs!$D$12*Inputs!$I$12+Inputs!$D$13*Inputs!$I$13+Inputs!$D$14*Inputs!$I$14+Inputs!$D$15*Inputs!$I$15+Inputs!$D$16*Inputs!$I$16) -> 0.7585998 | F12: =(Inputs!$D$12*Inputs!$I$12*Chemistry_Daily!F12+Inputs!$D$13*Inputs!$I$13*Chemistry_Daily!O12+Inputs!$D$14*Inputs!$I$14*Chemistry_Daily!X12+Inputs!$D$15*Inputs!$I$15*Chemistry_Daily!AG12+Inputs!$D$16*Inputs!$I$16*Chemistry_Daily!AP12)/(Inputs!$D$12*Inputs!$I$12+Inputs!$D$13*Inputs!$I$13+Inputs!$D$14*Inputs!$I$14+Inputs!$D$15*Inputs!$I$15+Inputs!$D$16*Inputs!$I$16) -> 36.739161 | G12: =(Inputs!$D$12*Inputs!$I$12*Chemistry_Daily!G12+Inputs!$D$13*Inputs!$I$13*Chemistry_Daily!P12+Inputs!$D$14*Inputs!$I$14*Chemistry_Daily!Y12+Inputs!$D$15*Inputs!$I$15*Chemistry_Daily!AH12+Inputs!$D$16*Inputs!$I$16*Chemistry_Daily!AQ12)/(Inputs!$D$12*Inputs!$I$12+Inputs!$D$13*Inputs!$I$13+Inputs!$D$14*Inputs!$I$14+Inputs!$D$15*Inputs!$I$15+Inputs!$D$16*Inputs!$I$16) -> 24.964753 | H12: =(Inputs!$D$12*Inputs!$I$12*BAC_ARC_Daily!B12+Inputs!$D$13*Inputs!$I$13*BAC_ARC_Daily!I12+Inputs!$D$14*Inputs!$I$14*BAC_ARC_Daily!P12+Inputs!$D$15*Inputs!$I$15*BAC_ARC_Daily!W12+Inputs!$D$16*Inputs!$I$16*BAC_ARC_Daily!AD12)/(Inputs!$D$12*Inputs!$I$12+Inputs!$D$13*Inputs!$I$13+Inputs!$D$14*Inputs!$I$14+Inputs!$D$15*Inputs!$I$15+Inputs!$D$16*Inputs!$I$16) -> 1160702.1 | I12: =(Inputs!$D$12*Inputs!$I$12*BAC_ARC_Daily!C12+Inputs!$D$13*Inputs!$I$13*BAC_ARC_Daily!J12+Inputs!$D$14*Inputs!$I$14*BAC_ARC_Daily!Q12+Inputs!$D$15*Inputs!$I$15*BAC_ARC_Daily!X12+Inputs!$D$16*Inputs!$I$16*BAC_ARC_Daily!AE12)/(Inputs!$D$12*Inputs!$I$12+Inputs!$D$13*Inputs!$I$13+Inputs!$D$14*Inputs!$I$14+Inputs!$D$15*Inputs!$I$15+Inputs!$D$16*Inputs!$I$16) -> 10901391
A13: 8 | B13: =(Inputs!$D$12*Inputs!$I$12*Chemistry_Daily!B13+Inputs!$D$13*Inputs!$I$13*Chemistry_Daily!K13+Inputs!$D$14*Inputs!$I$14*Chemistry_Daily!T13+Inputs!$D$15*Inputs!$I$15*Chemistry_Daily!AC13+Inputs!$D$16*Inputs!$I$16*Chemistry_Daily!AL13)/(Inputs!$D$12*Inputs!$I$12+Inputs!$D$13*Inputs!$I$13+Inputs!$D$14*Inputs!$I$14+Inputs!$D$15*Inputs!$I$15+Inputs!$D$16*Inputs!$I$16) -> 5.2231599e-06 | C13: =IF(B13>0,-LOG10(B13),"") -> 5.2820667 | D13: =(Inputs!$D$12*Inputs!$I$12*Chemistry_Daily!D13+Inputs!$D$13*Inputs!$I$13*Chemistry_Daily!M13+Inputs!$D$14*Inputs!$I$14*Chemistry_Daily!V13+Inputs!$D$15*Inputs!$I$15*Chemistry_Daily!AE13+Inputs!$D$16*Inputs!$I$16*Chemistry_Daily!AN13)/(Inputs!$D$12*Inputs!$I$12+Inputs!$D$13*Inputs!$I$13+Inputs!$D$14*Inputs!$I$14+Inputs!$D$15*Inputs!$I$15+Inputs!$D$16*Inputs!$I$16) -> 2.0766068 | E13: =(Inputs!$D$12*Inputs!$I$12*Chemistry_Daily!E13+Inputs!$D$13*Inputs!$I$13*Chemistry_Daily!N13+Inputs!$D$14*Inputs!$I$14*Chemistry_Daily!W13+Inputs!$D$15*Inputs!$I$15*Chemistry_Daily!AF13+Inputs!$D$16*Inputs!$I$16*Chemistry_Daily!AO13)/(Inputs!$D$12*Inputs!$I$12+Inputs!$D$13*Inputs!$I$13+Inputs!$D$14*Inputs!$I$14+Inputs!$D$15*Inputs!$I$15+Inputs!$D$16*Inputs!$I$16) -> 0.82419604 | F13: =(Inputs!$D$12*Inputs!$I$12*Chemistry_Daily!F13+Inputs!$D$13*Inputs!$I$13*Chemistry_Daily!O13+Inputs!$D$14*Inputs!$I$14*Chemistry_Daily!X13+Inputs!$D$15*Inputs!$I$15*Chemistry_Daily!AG13+Inputs!$D$16*Inputs!$I$16*Chemistry_Daily!AP13)/(Inputs!$D$12*Inputs!$I$12+Inputs!$D$13*Inputs!$I$13+Inputs!$D$14*Inputs!$I$14+Inputs!$D$15*Inputs!$I$15+Inputs!$D$16*Inputs!$I$16) -> 37.429577 | G13: =(Inputs!$D$12*Inputs!$I$12*Chemistry_Daily!G13+Inputs!$D$13*Inputs!$I$13*Chemistry_Daily!P13+Inputs!$D$14*Inputs!$I$14*Chemistry_Daily!Y13+Inputs!$D$15*Inputs!$I$15*Chemistry_Daily!AH13+Inputs!$D$16*Inputs!$I$16*Chemistry_Daily!AQ13)/(Inputs!$D$12*Inputs!$I$12+Inputs!$D$13*Inputs!$I$13+Inputs!$D$14*Inputs!$I$14+Inputs!$D$15*Inputs!$I$15+Inputs!$D$16*Inputs!$I$16) -> 25.202509 | H13: =(Inputs!$D$12*Inputs!$I$12*BAC_ARC_Daily!B13+Inputs!$D$13*Inputs!$I$13*BAC_ARC_Daily!I13+Inputs!$D$14*Inputs!$I$14*BAC_ARC_Daily!P13+Inputs!$D$15*Inputs!$I$15*BAC_ARC_Daily!W13+Inputs!$D$16*Inputs!$I$16*BAC_ARC_Daily!AD13)/(Inputs!$D$12*Inputs!$I$12+Inputs!$D$13*Inputs!$I$13+Inputs!$D$14*Inputs!$I$14+Inputs!$D$15*Inputs!$I$15+Inputs!$D$16*Inputs!$I$16) -> 1136132 | I13: =(Inputs!$D$12*Inputs!$I$12*BAC_ARC_Daily!C13+Inputs!$D$13*Inputs!$I$13*BAC_ARC_Daily!J13+Inputs!$D$14*Inputs!$I$14*BAC_ARC_Daily!Q13+Inputs!$D$15*Inputs!$I$15*BAC_ARC_Daily!X13+Inputs!$D$16*Inputs!$I$16*BAC_ARC_Daily!AE13)/(Inputs!$D$12*Inputs!$I$12+Inputs!$D$13*Inputs!$I$13+Inputs!$D$14*Inputs!$I$14+Inputs!$D$15*Inputs!$I$15+Inputs!$D$16*Inputs!$I$16) -> 10728032
A14: 9 | B14: =(Inputs!$D$12*Inputs!$I$12*Chemistry_Daily!B14+Inputs!$D$13*Inputs!$I$13*Chemistry_Daily!K14+Inputs!$D$14*Inputs!$I$14*Chemistry_Daily!T14+Inputs!$D$15*Inputs!$I$15*Chemistry_Daily!AC14+Inputs!$D$16*Inputs!$I$16*Chemistry_Daily!AL14)/(Inputs!$D$12*Inputs!$I$12+Inputs!$D$13*Inputs!$I$13+Inputs!$D$14*Inputs!$I$14+Inputs!$D$15*Inputs!$I$15+Inputs!$D$16*Inputs!$I$16) -> 5.7899553e-06 | C14: =IF(B14>0,-LOG10(B14),"") -> 5.2373248 | D14: =(Inputs!$D$12*Inputs!$I$12*Chemistry_Daily!D14+Inputs!$D$13*Inputs!$I$13*Chemistry_Daily!M14+Inputs!$D$14*Inputs!$I$14*Chemistry_Daily!V14+Inputs!$D$15*Inputs!$I$15*Chemistry_Daily!AE14+Inputs!$D$16*Inputs!$I$16*Chemistry_Daily!AN14)/(Inputs!$D$12*Inputs!$I$12+Inputs!$D$13*Inputs!$I$13+Inputs!$D$14*Inputs!$I$14+Inputs!$D$15*Inputs!$I$15+Inputs!$D$16*Inputs!$I$16) -> 2.0468786 | E14: =(Inputs!$D$12*Inputs!$I$12*Chemistry_Daily!E14+Inputs!$D$13*Inputs!$I$13*Chemistry_Daily!N14+Inputs!$D$14*Inputs!$I$14*Chemistry_Daily!W14+Inputs!$D$15*Inputs!$I$15*Chemistry_Daily!AF14+Inputs!$D$16*Inputs!$I$16*Chemistry_Daily!AO14)/(Inputs!$D$12*Inputs!$I$12+Inputs!$D$13*Inputs!$I$13+Inputs!$D$14*Inputs!$I$14+Inputs!$D$15*Inputs!$I$15+Inputs!$D$16*Inputs!$I$16) -> 0.888256 | F14: =(Inputs!$D$12*Inputs!$I$12*Chemistry_Daily!F14+Inputs!$D$13*Inputs!$I$13*Chemistry_Daily!O14+Inputs!$D$14*Inputs!$I$14*Chemistry_Daily!X14+Inputs!$D$15*Inputs!$I$15*Chemistry_Daily!AG14+Inputs!$D$16*Inputs!$I$16*Chemistry_Daily!AP14)/(Inputs!$D$12*Inputs!$I$12+Inputs!$D$13*Inputs!$I$13+Inputs!$D$14*Inputs!$I$14+Inputs!$D$15*Inputs!$I$15+Inputs!$D$16*Inputs!$I$16) -> 38.103812 | G14: =(Inputs!$D$12*Inputs!$I$12*Chemistry_Daily!G14+Inputs!$D$13*Inputs!$I$13*Chemistry_Daily!P14+Inputs!$D$14*Inputs!$I$14*Chemistry_Daily!Y14+Inputs!$D$15*Inputs!$I$15*Chemistry_Daily!AH14+Inputs!$D$16*Inputs!$I$16*Chemistry_Daily!AQ14)/(Inputs!$D$12*Inputs!$I$12+Inputs!$D$13*Inputs!$I$13+Inputs!$D$14*Inputs!$I$14+Inputs!$D$15*Inputs!$I$15+Inputs!$D$16*Inputs!$I$16) -> 25.434199 | H14: =(Inputs!$D$12*Inputs!$I$12*BAC_ARC_Daily!B14+Inputs!$D$13*Inputs!$I$13*BAC_ARC_Daily!I14+Inputs!$D$14*Inputs!$I$14*BAC_ARC_Daily!P14+Inputs!$D$15*Inputs!$I$15*BAC_ARC_Daily!W14+Inputs!$D$16*Inputs!$I$16*BAC_ARC_Daily!AD14)/(Inputs!$D$12*Inputs!$I$12+Inputs!$D$13*Inputs!$I$13+Inputs!$D$14*Inputs!$I$14+Inputs!$D$15*Inputs!$I$15+Inputs!$D$16*Inputs!$I$16) -> 1112115.4 | I14: =(Inputs!$D$12*Inputs!$I$12*BAC_ARC_Daily!C14+Inputs!$D$13*Inputs!$I$13*BAC_ARC_Daily!J14+Inputs!$D$14*Inputs!$I$14*BAC_ARC_Daily!Q14+Inputs!$D$15*Inputs!$I$15*BAC_ARC_Daily!X14+Inputs!$D$16*Inputs!$I$16*BAC_ARC_Daily!AE14)/(Inputs!$D$12*Inputs!$I$12+Inputs!$D$13*Inputs!$I$13+Inputs!$D$14*Inputs!$I$14+Inputs!$D$15*Inputs!$I$15+Inputs!$D$16*Inputs!$I$16) -> 10559063
A15: 10 | B15: =(Inputs!$D$12*Inputs!$I$12*Chemistry_Daily!B15+Inputs!$D$13*Inputs!$I$13*Chemistry_Daily!K15+Inputs!$D$14*Inputs!$I$14*Chemistry_Daily!T15+Inputs!$D$15*Inputs!$I$15*Chemistry_Daily!AC15+Inputs!$D$16*Inputs!$I$16*Chemistry_Daily!AL15)/(Inputs!$D$12*Inputs!$I$12+Inputs!$D$13*Inputs!$I$13+Inputs!$D$14*Inputs!$I$14+Inputs!$D$15*Inputs!$I$15+Inputs!$D$16*Inputs!$I$16) -> 6.3435764e-06 | C15: =IF(B15>0,-LOG10(B15),"") -> 5.1976658 | D15: =(Inputs!$D$12*Inputs!$I$12*Chemistry_Daily!D15+Inputs!$D$13*Inputs!$I$13*Chemistry_Daily!M15+Inputs!$D$14*Inputs!$I$14*Chemistry_Daily!V15+Inputs!$D$15*Inputs!$I$15*Chemistry_Daily!AE15+Inputs!$D$16*Inputs!$I$16*Chemistry_Daily!AN15)/(Inputs!$D$12*Inputs!$I$12+Inputs!$D$13*Inputs!$I$13+Inputs!$D$14*Inputs!$I$14+Inputs!$D$15*Inputs!$I$15+Inputs!$D$16*Inputs!$I$16) -> 2.0179473 | E15: =(Inputs!$D$12*Inputs!$I$12*Chemistry_Daily!E15+Inputs!$D$13*Inputs!$I$13*Chemistry_Daily!N15+Inputs!$D$14*Inputs!$I$14*Chemistry_Daily!W15+Inputs!$D$15*Inputs!$I$15*Chemistry_Daily!AF15+Inputs!$D$16*Inputs!$I$16*Chemistry_Daily!AO15)/(Inputs!$D$12*Inputs!$I$12+Inputs!$D$13*Inputs!$I$13+Inputs!$D$14*Inputs!$I$14+Inputs!$D$15*Inputs!$I$15+Inputs!$D$16*Inputs!$I$16) -> 0.95081959 | F15: =(Inputs!$D$12*Inputs!$I$12*Chemistry_Daily!F15+Inputs!$D$13*Inputs!$I$13*Chemistry_Daily!O15+Inputs!$D$14*Inputs!$I$14*Chemistry_Daily!X15+Inputs!$D$15*Inputs!$I$15*Chemistry_Daily!AG15+Inputs!$D$16*Inputs!$I$16*Chemistry_Daily!AP15)/(Inputs!$D$12*Inputs!$I$12+Inputs!$D$13*Inputs!$I$13+Inputs!$D$14*Inputs!$I$14+Inputs!$D$15*Inputs!$I$15+Inputs!$D$16*Inputs!$I$16) -> 38.762288 | G15: =(Inputs!$D$12*Inputs!$I$12*Chemistry_Daily!G15+Inputs!$D$13*Inputs!$I$13*Chemistry_Daily!P15+Inputs!$D$14*Inputs!$I$14*Chemistry_Daily!Y15+Inputs!$D$15*Inputs!$I$15*Chemistry_Daily!AH15+Inputs!$D$16*Inputs!$I$16*Chemistry_Daily!AQ15)/(Inputs!$D$12*Inputs!$I$12+Inputs!$D$13*Inputs!$I$13+Inputs!$D$14*Inputs!$I$14+Inputs!$D$15*Inputs!$I$15+Inputs!$D$16*Inputs!$I$16) -> 25.660001 | H15: =(Inputs!$D$12*Inputs!$I$12*BAC_ARC_Daily!B15+Inputs!$D$13*Inputs!$I$13*BAC_ARC_Daily!I15+Inputs!$D$14*Inputs!$I$14*BAC_ARC_Daily!P15+Inputs!$D$15*Inputs!$I$15*BAC_ARC_Daily!W15+Inputs!$D$16*Inputs!$I$16*BAC_ARC_Daily!AD15)/(Inputs!$D$12*Inputs!$I$12+Inputs!$D$13*Inputs!$I$13+Inputs!$D$14*Inputs!$I$14+Inputs!$D$15*Inputs!$I$15+Inputs!$D$16*Inputs!$I$16) -> 1088639 | I15: =(Inputs!$D$12*Inputs!$I$12*BAC_ARC_Daily!C15+Inputs!$D$13*Inputs!$I$13*BAC_ARC_Daily!J15+Inputs!$D$14*Inputs!$I$14*BAC_ARC_Daily!Q15+Inputs!$D$15*Inputs!$I$15*BAC_ARC_Daily!X15+Inputs!$D$16*Inputs!$I$16*BAC_ARC_Daily!AE15)/(Inputs!$D$12*Inputs!$I$12+Inputs!$D$13*Inputs!$I$13+Inputs!$D$14*Inputs!$I$14+Inputs!$D$15*Inputs!$I$15+Inputs!$D$16*Inputs!$I$16) -> 10394355
A16: 11 | B16: =(Inputs!$D$12*Inputs!$I$12*Chemistry_Daily!B16+Inputs!$D$13*Inputs!$I$13*Chemistry_Daily!K16+Inputs!$D$14*Inputs!$I$14*Chemistry_Daily!T16+Inputs!$D$15*Inputs!$I$15*Chemistry_Daily!AC16+Inputs!$D$16*Inputs!$I$16*Chemistry_Daily!AL16)/(Inputs!$D$12*Inputs!$I$12+Inputs!$D$13*Inputs!$I$13+Inputs!$D$14*Inputs!$I$14+Inputs!$D$15*Inputs!$I$15+Inputs!$D$16*Inputs!$I$16) -> 6.8843612e-06 | C16: =IF(B16>0,-LOG10(B16),"") -> 5.1621364 | D16: =(Inputs!$D$12*Inputs!$I$12*Chemistry_Daily!D16+Inputs!$D$13*Inputs!$I$13*Chemistry_Daily!M16+Inputs!$D$14*Inputs!$I$14*Chemistry_Daily!V16+Inputs!$D$15*Inputs!$I$15*Chemistry_Daily!AE16+Inputs!$D$16*Inputs!$I$16*Chemistry_Daily!AN16)/(Inputs!$D$12*Inputs!$I$12+Inputs!$D$13*Inputs!$I$13+Inputs!$D$14*Inputs!$I$14+Inputs!$D$15*Inputs!$I$15+Inputs!$D$16*Inputs!$I$16) -> 1.989788 | E16: =(Inputs!$D$12*Inputs!$I$12*Chemistry_Daily!E16+Inputs!$D$13*Inputs!$I$13*Chemistry_Daily!N16+Inputs!$D$14*Inputs!$I$14*Chemistry_Daily!W16+Inputs!$D$15*Inputs!$I$15*Chemistry_Daily!AF16+Inputs!$D$16*Inputs!$I$16*Chemistry_Daily!AO16)/(Inputs!$D$12*Inputs!$I$12+Inputs!$D$13*Inputs!$I$13+Inputs!$D$14*Inputs!$I$14+Inputs!$D$15*Inputs!$I$15+Inputs!$D$16*Inputs!$I$16) -> 1.0119255 | F16: =(Inputs!$D$12*Inputs!$I$12*Chemistry_Daily!F16+Inputs!$D$13*Inputs!$I$13*Chemistry_Daily!O16+Inputs!$D$14*Inputs!$I$14*Chemistry_Daily!X16+Inputs!$D$15*Inputs!$I$15*Chemistry_Daily!AG16+Inputs!$D$16*Inputs!$I$16*Chemistry_Daily!AP16)/(Inputs!$D$12*Inputs!$I$12+Inputs!$D$13*Inputs!$I$13+Inputs!$D$14*Inputs!$I$14+Inputs!$D$15*Inputs!$I$15+Inputs!$D$16*Inputs!$I$16) -> 39.405412 | G16: =(Inputs!$D$12*Inputs!$I$12*Chemistry_Daily!G16+Inputs!$D$13*Inputs!$I$13*Chemistry_Daily!P16+Inputs!$D$14*Inputs!$I$14*Chemistry_Daily!Y16+Inputs!$D$15*Inputs!$I$15*Chemistry_Daily!AH16+Inputs!$D$16*Inputs!$I$16*Chemistry_Daily!AQ16)/(Inputs!$D$12*Inputs!$I$12+Inputs!$D$13*Inputs!$I$13+Inputs!$D$14*Inputs!$I$14+Inputs!$D$15*Inputs!$I$15+Inputs!$D$16*Inputs!$I$16) -> 25.88009 | H16: =(Inputs!$D$12*Inputs!$I$12*BAC_ARC_Daily!B16+Inputs!$D$13*Inputs!$I$13*BAC_ARC_Daily!I16+Inputs!$D$14*Inputs!$I$14*BAC_ARC_Daily!P16+Inputs!$D$15*Inputs!$I$15*BAC_ARC_Daily!W16+Inputs!$D$16*Inputs!$I$16*BAC_ARC_Daily!AD16)/(Inputs!$D$12*Inputs!$I$12+Inputs!$D$13*Inputs!$I$13+Inputs!$D$14*Inputs!$I$14+Inputs!$D$15*Inputs!$I$15+Inputs!$D$16*Inputs!$I$16) -> 1065689.6 | I16: =(Inputs!$D$12*Inputs!$I$12*BAC_ARC_Daily!C16+Inputs!$D$13*Inputs!$I$13*BAC_ARC_Daily!J16+Inputs!$D$14*Inputs!$I$14*BAC_ARC_Daily!Q16+Inputs!$D$15*Inputs!$I$15*BAC_ARC_Daily!X16+Inputs!$D$16*Inputs!$I$16*BAC_ARC_Daily!AE16)/(Inputs!$D$12*Inputs!$I$12+Inputs!$D$13*Inputs!$I$13+Inputs!$D$14*Inputs!$I$14+Inputs!$D$15*Inputs!$I$15+Inputs!$D$16*Inputs!$I$16) -> 10233784
... A26: 21 | B26: =(Inputs!$D$12*Inputs!$I$12*Chemistry_Daily!B26+Inputs!$D$13*Inputs!$I$13*Chemistry_Daily!K26+Inputs!$D$14*Inputs!$I$14*Chemistry_Daily!T26+Inputs!$D$15*Inputs!$I$15*Chemistry_Daily!AC26+Inputs!$D$16*Inputs!$I$16*Chemistry_Daily!AL26)/(Inputs!$D$12*Inputs!$I$12+Inputs!$D$13*Inputs!$I$13+Inputs!$D$14*Inputs!$I$14+Inputs!$D$15*Inputs!$I$15+Inputs!$D$16*Inputs!$I$16) -> 1.1653812e-05 | C26: =IF(B26>0,-LOG10(B26),"") -> 4.933532 | D26: =(Inputs!$D$12*Inputs!$I$12*Chemistry_Daily!D26+Inputs!$D$13*Inputs!$I$13*Chemistry_Daily!M26+Inputs!$D$14*Inputs!$I$14*Chemistry_Daily!V26+Inputs!$D$15*Inputs!$I$15*Chemistry_Daily!AE26+Inputs!$D$16*Inputs!$I$16*Chemistry_Daily!AN26)/(Inputs!$D$12*Inputs!$I$12+Inputs!$D$13*Inputs!$I$13+Inputs!$D$14*Inputs!$I$14+Inputs!$D$15*Inputs!$I$15+Inputs!$D$16*Inputs!$I$16) -> 1.7457559 | E26: =(Inputs!$D$12*Inputs!$I$12*Chemistry_Daily!E26+Inputs!$D$13*Inputs!$I$13*Chemistry_Daily!N26+Inputs!$D$14*Inputs!$I$14*Chemistry_Daily!W26+Inputs!$D$15*Inputs!$I$15*Chemistry_Daily!AF26+Inputs!$D$16*Inputs!$I$16*Chemistry_Daily!AO26)/(Inputs!$D$12*Inputs!$I$12+Inputs!$D$13*Inputs!$I$13+Inputs!$D$14*Inputs!$I$14+Inputs!$D$15*Inputs!$I$15+Inputs!$D$16*Inputs!$I$16) -> 1.5505486 | F26: =(Inputs!$D$12*Inputs!$I$12*Chemistry_Daily!F26+Inputs!$D$13*Inputs!$I$13*Chemistry_Daily!O26+Inputs!$D$14*Inputs!$I$14*Chemistry_Daily!X26+Inputs!$D$15*Inputs!$I$15*Chemistry_Daily!AG26+Inputs!$D$16*Inputs!$I$16*Chemistry_Daily!AP26)/(Inputs!$D$12*Inputs!$I$12+Inputs!$D$13*Inputs!$I$13+Inputs!$D$14*Inputs!$I$14+Inputs!$D$15*Inputs!$I$15+Inputs!$D$16*Inputs!$I$16) -> 45.073905 | G26: =(Inputs!$D$12*Inputs!$I$12*Chemistry_Daily!G26+Inputs!$D$13*Inputs!$I$13*Chemistry_Daily!P26+Inputs!$D$14*Inputs!$I$14*Chemistry_Daily!Y26+Inputs!$D$15*Inputs!$I$15*Chemistry_Daily!AH26+Inputs!$D$16*Inputs!$I$16*Chemistry_Daily!AQ26)/(Inputs!$D$12*Inputs!$I$12+Inputs!$D$13*Inputs!$I$13+Inputs!$D$14*Inputs!$I$14+Inputs!$D$15*Inputs!$I$15+Inputs!$D$16*Inputs!$I$16) -> 27.800716 | H26: =(Inputs!$D$12*Inputs!$I$12*BAC_ARC_Daily!B26+Inputs!$D$13*Inputs!$I$13*BAC_ARC_Daily!I26+Inputs!$D$14*Inputs!$I$14*BAC_ARC_Daily!P26+Inputs!$D$15*Inputs!$I$15*BAC_ARC_Daily!W26+Inputs!$D$16*Inputs!$I$16*BAC_ARC_Daily!AD26)/(Inputs!$D$12*Inputs!$I$12+Inputs!$D$13*Inputs!$I$13+Inputs!$D$14*Inputs!$I$14+Inputs!$D$15*Inputs!$I$15+Inputs!$D$16*Inputs!$I$16) -> 862547 | I26: =(Inputs!$D$12*Inputs!$I$12*BAC_ARC_Daily!C26+Inputs!$D$13*Inputs!$I$13*BAC_ARC_Daily!J26+Inputs!$D$14*Inputs!$I$14*BAC_ARC_Daily!Q26+Inputs!$D$15*Inputs!$I$15*BAC_ARC_Daily!X26+Inputs!$D$16*Inputs!$I$16*BAC_ARC_Daily!AE26)/(Inputs!$D$12*Inputs!$I$12+Inputs!$D$13*Inputs!$I$13+Inputs!$D$14*Inputs!$I$14+Inputs!$D$15*Inputs!$I$15+Inputs!$D$16*Inputs!$I$16) -> 8831198

Sheet Chemistry_Daily
A1: Chemistry Daily Tracking (mixing / dilution only)
A3: R1 | J3: R2 | S3: R3 | AB3: R4 | AK3: R5
A4: Day | B4: H+ | C4: pH | D4: Alkalinity | E4: TVFA | F4: COD | G4: VS | H4: TVFA/Alk | J4: Day | K4: H+ | L4: pH | M4: Alkalinity | N4: TVFA | O4: COD | P4: VS | Q4: TVFA/Alk | S4: Day | T4: H+ | U4: pH | V4: Alkalinity | W4: TVFA | X4: COD | Y4: VS | Z4: TVFA/Alk | AB4: Day | AC4: H+ | AD4: pH | AE4: Alkalinity | AF4: TVFA | AG4: COD | AH4: VS | AI4: TVFA/Alk | AK4: Day | AL4: H+ | AM4: pH | AN4: Alkalinity | AO4: TVFA | AP4: COD | AQ4: VS | AR4: TVFA/Alk
A5: 0 | B5: =IF(Inputs!$B$35="", "", 10^(-Inputs!$B$35)) -> 6.3095734e-08 | C5: =IF(Inputs!$B$35="", "", Inputs!$B$35) -> 7.2 | D5: =IF(Inputs!$C$35="", "", Inputs!$C$35) -> 3.5 | E5: =IF(Inputs!$D$35="", "", Inputs!$D$35) -> 0.09 | F5: =IF(Inputs!$E$35="", "", Inputs!$E$35) -> 25.6 | G5: =IF(Inputs!$F$35="", "", Inputs!$F$35) -> 18.1 | H5: =IF(D5<>0,E5/D5,"") -> 0.025714286 | J5: 0 | K5: =IF(Inputs!$B$36="", "", 10^(-Inputs!$B$36)) -> 6.3095734e-08 | L5: =IF(Inputs!$B$36="", "", Inputs!$B$36) -> 7.2 | M5: =IF(Inputs!$C$36="", "", Inputs!$C$36) -> 3.5 | N5: =IF(Inputs!$D$36="", "", Inputs!$D$36) -> 0.091 | O5: =IF(Inputs!$E$36="", "", Inputs!$E$36) -> 24.6 | P5: =IF(Inputs!$F$36="", "", Inputs!$F$36) -> 17.9 | Q5: =IF(M5<>0,N5/M5,"") -> 0.026 | S5: 0 | T5: =IF(Inputs!$B$37="", "", 10^(-Inputs!$B$37)) -> 6.3095734e-08 | U5: =IF(Inputs!$B$37="", "", Inputs!$B$37) -> 7.2 | V5: =IF(Inputs!$C$37="", "", Inputs!$C$37) -> 3.8 | W5: =IF(Inputs!$D$37="", "", Inputs!$D$37) -> 0.0919 | X5: =IF(Inputs!$E$37="", "", Inputs!$E$37) -> 24 | Y5: =IF(Inputs!$F$37="", "", Inputs!$F$37) -> 17.5 | Z5: =IF(V5<>0,W5/V5,"") -> 0.024184211 | AB5: 0 | AC5: =IF(Inputs!$B$38="", "", 10^(-Inputs!$B$38)) -> 3.1622777e-07 | AD5: =IF(Inputs!$B$38="", "", Inputs!$B$38) -> 6.5 | AE5: =IF(Inputs!$C$38="", "", Inputs!$C$38) -> 0.713 | AF5: =IF(Inputs!$D$38="", "", Inputs!$D$38) -> 0.513 | AG5: =IF(Inputs!$E$38="", "", Inputs!$E$38) -> 40.5 | AH5: =IF(Inputs!$F$38="", "", Inputs!$F$38) -> 30.5 | AI5: =IF(AE5<>0,AF5/AE5,"") -> 0.71949509 | AK5: 0 | AL5: =IF(Inputs!$B$39="", "", 10^(-Inputs!$B$39)) -> 3.1622777e-07 | AM5: =IF(Inputs!$B$39="", "", Inputs!$B$39) -> 6.5 | AN5: =IF(Inputs!$C$39="", "", Inputs!$C$39) -> 0.626 | AO5: =IF(Inputs!$D$39="", "", Inputs!$D$39) -> 0.433 | AP5: =IF(Inputs!$E$39="", "", Inputs!$E$39) -> 40.3 | AQ5: =IF(Inputs!$F$39="", "", Inputs!$F$39) -> 30 | AR5: =IF(AN5<>0,AO5/AN5,"") -> 0.69169329
A6: 1 | B6: =IF(B5="","",B5+Inputs!$B$5/Inputs!$B$12*(Inputs!$C$12*(IF(Inputs!$C$23>0,10^(-Inputs!$C$23),0)-B5)+Inputs!$D$12*(Reservoir!$B$5-B5)+Inputs!$E$12*(IF(Inputs!$D$23>0,10^(-Inputs!$D$23),0)-B5))) -> 1.1486687e-06 | C6: =IF(B6>0,-LOG10(B6),"") -> 5.9398052 | D6: =IF(D5="","",D5+Inputs!$B$5/Inputs!$B$12*(Inputs!$C$12*(Inputs!$C$24-D5)+Inputs!$D$12*(Reservoir!$D$5-D5)+Inputs!$E$12*(Inputs!$D$24-D5))) -> 3.399729 | E6: =IF(E5="","",E5+Inputs!$B$5/Inputs!$B$12*(Inputs!$C$12*(Inputs!$C$25-E5)+Inputs!$D$12*(Reservoir!$E$5-E5)+Inputs!$E$12*(Inputs!$D$25-E5))) -> 0.2159656 | F6: =IF(F5="","",F5+Inputs!$B$5/Inputs!$B$12*(Inputs!$C$12*(Inputs!$C$26-F5)+Inputs!$D$12*(Reservoir!$F$5-F5)+Inputs!$E$12*(Inputs!$D$26-F5))) -> 26.91469 | G6: =IF(G5="","",G5+Inputs!$B$5/Inputs!$B$12*(Inputs!$C$12*(Inputs!$C$27-G5)+Inputs!$D$12*(Reservoir!$G$5-G5)+Inputs!$E$12*(Inputs!$D$27-G5))) -> 18.744084 | H6: =IF(D6<>0,E6/D6,"") -> 0.063524356 | J6: 1 | K6: =IF(K5="","",K5+Inputs!$B$5/Inputs!$B$13*(Inputs!$C$13*(IF(Inputs!$C$23>0,10^(-Inputs!$C$23),0)-K5)+Inputs!$D$13*(Reservoir!$B$5-K5)+Inputs!$E$13*(IF(Inputs!$D$23>0,10^(-Inputs!$D$23),0)-K5))) -> 1.1486687e-06 | L6: =IF(K6>0,-LOG10(K6),"") -> 5.9398052 | M6: =IF(M5="","",M5+Inputs!$B$5/Inputs!$B$13*(Inputs!$C$13*(Inputs!$C$24-M5)+Inputs!$D$13*(Reservoir!$D$5-M5)+Inputs!$E$13*(Inputs!$D$24-M5))) -> 3.399729 | N6: =IF(N5="","",N5+Inputs!$B$5/Inputs!$B$13*(Inputs!$C$13*(Inputs!$C$25-N5)+Inputs!$D$13*(Reservoir!$E$5-N5)+Inputs!$E$13*(Inputs!$D$25-N5))) -> 0.21691417 | O6: =IF(O5="","",O5+Inputs!$B$5/Inputs!$B$13*(Inputs!$C$13*(Inputs!$C$26-O5)+Inputs!$D$13*(Reservoir!$F$5-O5)+Inputs!$E$13*(Inputs!$D$26-O5))) -> 25.966118 | P6: =IF(P5="","",P5+Inputs!$B$5/Inputs!$B$13*(Inputs!$C$13*(Inputs!$C$27-P5)+Inputs!$D$13*(Reservoir!$G$5-P5)+Inputs!$E$13*(Inputs!$D$27-P5))) -> 18.55437 | Q6: =IF(M6<>0,N6/M6,"") -> 0.06380337 | S6: 1 | T6: =IF(T5="","",T5+Inputs!$B$5/Inputs!$B$14*(Inputs!$C$14*(IF(Inputs!$C$23>0,10^(-Inputs!$C$23),0)-T5)+Inputs!$D$14*(Reservoir!$B$5-T5)+Inputs!$E$14*(IF(Inputs!$D$23>0,10^(-Inputs!$D$23),0)-T5))) -> 1.5530375e-06 | U6: =IF(T6>0,-LOG10(T6),"") -> 5.808818 | V6: =IF(V5="","",V5+Inputs!$B$5/Inputs!$B$14*(Inputs!$C$14*(Inputs!$C$24-V5)+Inputs!$D$14*(Reservoir!$D$5-V5)+Inputs!$E$14*(Inputs!$D$24-V5))) -> 3.6933752 | W6: =IF(W5="","",W5+Inputs!$B$5/Inputs!$B$14*(Inputs!$C$14*(Inputs!$C$25-W5)+Inputs!$D$14*(Reservoir!$E$5-W5)+Inputs!$E$14*(Inputs!$D$25-W5))) -> 0.2560673 | X6: =IF(X5="","",X5+Inputs!$B$5/Inputs!$B$14*(Inputs!$C$14*(Inputs!$C$26-X5)+Inputs!$D$14*(Reservoir!$F$5-X5)+Inputs!$E$14*(Inputs!$D$26-X5))) -> 25.432895 | Y6: =IF(Y5="","",Y5+Inputs!$B$5/Inputs!$B$14*(Inputs!$C$14*(Inputs!$C$27-Y5)+Inputs!$D$14*(Reservoir!$G$5-Y5)+Inputs!$E$14*(Inputs!$D$27-Y5))) -> 18.234552 | Z6: =IF(V6<>0,W6/V6,"") -> 0.069331516 | AB6: 1 | AC6: =IF(AC5="","",AC5+Inputs!$B$5/Inputs!$B$15*(Inputs!$C$15*(IF(Inputs!$C$23>0,10^(-Inputs!$C$23),0)-AC5)+Inputs!$D$15*(Reservoir!$B$5-AC5)+Inputs!$E$15*(IF(Inputs!$D$23>0,10^(-Inputs!$D$23),0)-AC5))) -> 3.1241411e-07 | AD6: =IF(AC6>0,-LOG10(AC6),"") -> 6.5052694 | AE6: =IF(AE5="","",AE5+Inputs!$B$5/Inputs!$B$15*(Inputs!$C$15*(Inputs!$C$24-AE5)+Inputs!$D$15*(Reservoir!$D$5-AE5)+Inputs!$E$15*(Inputs!$D$24-AE5))) -> 0.76217189 | AF6: =IF(AF5="","",AF5+Inputs!$B$5/Inputs!$B$15*(Inputs!$C$15*(Inputs!$C$25-AF5)+Inputs!$D$15*(Reservoir!$E$5-AF5)+Inputs!$E$15*(Inputs!$D$25-AF5))) -> 0.50932274 | AG6: =IF(AG5="","",AG5+Inputs!$B$5/Inputs!$B$15*(Inputs!$C$15*(Inputs!$C$26-AG5)+Inputs!$D$15*(Reservoir!$F$5-AG5)+Inputs!$E$15*(Inputs!$D$26-AG5))) -> 40.56669 | AH6: =IF(AH5="","",AH5+Inputs!$B$5/Inputs!$B$15*(Inputs!$C$15*(Inputs!$C$27-AH5)+Inputs!$D$15*(Reservoir!$G$5-AH5)+Inputs!$E$15*(Inputs!$D$27-AH5))) -> 30.250084 | AI6: =IF(AE6<>0,AF6/AE6,"") -> 0.66825181 | AK6: 1 | AL6: =IF(AL5="","",AL5+Inputs!$B$5/Inputs!$B$16*(Inputs!$C$16*(IF(Inputs!$C$23>0,10^(-Inputs!$C$23),0)-AL5)+Inputs!$D$16*(Reservoir!$B$5-AL5)+Inputs!$E$16*(IF(Inputs!$D$23>0,10^(-Inputs!$D$23),0)-AL5))) -> 3.1241411e-07 | AM6: =IF(AL6>0,-LOG10(AL6),"") -> 6.5052694 | AN6: =IF(AN5="","",AN5+Inputs!$B$5/Inputs!$B$16*(Inputs!$C$16*(Inputs!$C$24-AN5)+Inputs!$D$16*(Reservoir!$D$5-AN5)+Inputs!$E$16*(Inputs!$D$24-AN5))) -> 0.67890046 | AO6: =IF(AO5="","",AO5+Inputs!$B$5/Inputs!$B$16*(Inputs!$C$16*(Inputs!$C$25-AO5)+Inputs!$D$16*(Reservoir!$E$5-AO5)+Inputs!$E$16*(Inputs!$D$25-AO5))) -> 0.43275131 | AP6: =IF(AP5="","",AP5+Inputs!$B$5/Inputs!$B$16*(Inputs!$C$16*(Inputs!$C$26-AP5)+Inputs!$D$16*(Reservoir!$F$5-AP5)+Inputs!$E$16*(Inputs!$D$26-AP5))) -> 40.375261 | AQ6: =IF(AQ5="","",AQ5+Inputs!$B$5/Inputs!$B$16*(Inputs!$C$16*(Inputs!$C$27-AQ5)+Inputs!$D$16*(Reservoir!$G$5-AQ5)+Inputs!$E$16*(Inputs!$D$27-AQ5))) -> 29.771513 | AR6: =IF(AN6<>0,AO6/AN6,"") -> 0.63742969
A7: 2 | B7: =IF(B6="","",B6+Inputs!$B$5/Inputs!$B$12*(Inputs!$C$12*(IF(Inputs!$C$23>0,10^(-Inputs!$C$23),0)-B6)+Inputs!$D$12*(Reservoir!$B$6-B6)+Inputs!$E$12*(IF(Inputs!$D$23>0,10^(-Inputs!$D$23),0)-B6))) -> 2.1963381e-06 | C7: =IF(B7>0,-LOG10(B7),"") -> 5.6583008 | D7: =IF(D6="","",D6+Inputs!$B$5/Inputs!$B$12*(Inputs!$C$12*(Inputs!$C$24-D6)+Inputs!$D$12*(Reservoir!$D$6-D6)+Inputs!$E$12*(Inputs!$D$24-D6))) -> 3.3036442 | E7: =IF(E6="","",E6+Inputs!$B$5/Inputs!$B$12*(Inputs!$C$12*(Inputs!$C$25-E6)+Inputs!$D$12*(Reservoir!$E$6-E6)+Inputs!$E$12*(Inputs!$D$25-E6))) -> 0.3374811 | F7: =IF(F6="","",F6+Inputs!$B$5/Inputs!$B$12*(Inputs!$C$12*(Inputs!$C$26-F6)+Inputs!$D$12*(Reservoir!$F$6-F6)+Inputs!$E$12*(Inputs!$D$26-F6))) -> 28.183117 | G7: =IF(G6="","",G6+Inputs!$B$5/Inputs!$B$12*(Inputs!$C$12*(Inputs!$C$27-G6)+Inputs!$D$12*(Reservoir!$G$6-G6)+Inputs!$E$12*(Inputs!$D$27-G6))) -> 19.362516 | H7: =IF(D7<>0,E7/D7,"") -> 0.10215419 | J7: 2 | K7: =IF(K6="","",K6+Inputs!$B$5/Inputs!$B$13*(Inputs!$C$13*(IF(Inputs!$C$23>0,10^(-Inputs!$C$23),0)-K6)+Inputs!$D$13*(Reservoir!$B$6-K6)+Inputs!$E$13*(IF(Inputs!$D$23>0,10^(-Inputs!$D$23),0)-K6))) -> 2.1963381e-06 | L7: =IF(K7>0,-LOG10(K7),"") -> 5.6583008 | M7: =IF(M6="","",M6+Inputs!$B$5/Inputs!$B$13*(Inputs!$C$13*(Inputs!$C$24-M6)+Inputs!$D$13*(Reservoir!$D$6-M6)+Inputs!$E$13*(Inputs!$D$24-M6))) -> 3.3036442 | N7: =IF(N6="","",N6+Inputs!$B$5/Inputs!$B$13*(Inputs!$C$13*(Inputs!$C$25-N6)+Inputs!$D$13*(Reservoir!$E$6-N6)+Inputs!$E$13*(Inputs!$D$25-N6))) -> 0.33838089 | O7: =IF(O6="","",O6+Inputs!$B$5/Inputs!$B$13*(Inputs!$C$13*(Inputs!$C$26-O6)+Inputs!$D$13*(Reservoir!$F$6-O6)+Inputs!$E$13*(Inputs!$D$26-O6))) -> 27.283329 | P7: =IF(P6="","",P6+Inputs!$B$5/Inputs!$B$13*(Inputs!$C$13*(Inputs!$C$27-P6)+Inputs!$D$13*(Reservoir!$G$6-P6)+Inputs!$E$13*(Inputs!$D$27-P6))) -> 19.182558 | Q7: =IF(M7<>0,N7/M7,"") -> 0.10242655 | S7: 2 | T7: =IF(T6="","",T6+Inputs!$B$5/Inputs!$B$14*(Inputs!$C$14*(IF(Inputs!$C$23>0,10^(-Inputs!$C$23),0)-T6)+Inputs!$D$14*(Reservoir!$B$6-T6)+Inputs!$E$14*(IF(Inputs!$D$23>0,10^(-Inputs!$D$23),0)-T6))) -> 2.9912612e-06 | U7: =IF(T7>0,-LOG10(T7),"") -> 5.5241457 | V7: =IF(V6="","",V6+Inputs!$B$5/Inputs!$B$14*(Inputs!$C$14*(Inputs!$C$24-V6)+Inputs!$D$14*(Reservoir!$D$6-V6)+Inputs!$E$14*(Inputs!$D$24-V6))) -> 3.5906837 | W7: =IF(W6="","",W6+Inputs!$B$5/Inputs!$B$14*(Inputs!$C$14*(Inputs!$C$25-W6)+Inputs!$D$14*(Reservoir!$E$6-W6)+Inputs!$E$14*(Inputs!$D$25-W6))) -> 0.41457552 | X7: =IF(X6="","",X6+Inputs!$B$5/Inputs!$B$14*(Inputs!$C$14*(Inputs!$C$26-X6)+Inputs!$D$14*(Reservoir!$F$6-X6)+Inputs!$E$14*(Inputs!$D$26-X6))) -> 26.819107 | Y7: =IF(Y6="","",Y6+Inputs!$B$5/Inputs!$B$14*(Inputs!$C$14*(Inputs!$C$27-Y6)+Inputs!$D$14*(Reservoir!$G$6-Y6)+Inputs!$E$14*(Inputs!$D$27-Y6))) -> 18.942592 | Z7: =IF(V7<>0,W7/V7,"") -> 0.11545866 | AB7: 2 | AC7: =IF(AC6="","",AC6+Inputs!$B$5/Inputs!$B$15*(Inputs!$C$15*(IF(Inputs!$C$23>0,10^(-Inputs!$C$23),0)-AC6)+Inputs!$D$15*(Reservoir!$B$6-AC6)+Inputs!$E$15*(IF(Inputs!$D$23>0,10^(-Inputs!$D$23),0)-AC6))) -> 3.2668976e-07 | AD7: =IF(AC7>0,-LOG10(AC7),"") -> 6.4858645 | AE7: =IF(AE6="","",AE6+Inputs!$B$5/Inputs!$B$15*(Inputs!$C$15*(Inputs!$C$24-AE6)+Inputs!$D$15*(Reservoir!$D$6-AE6)+Inputs!$E$15*(Inputs!$D$24-AE6))) -> 0.80826572 | AF7: =IF(AF6="","",AF6+Inputs!$B$5/Inputs!$B$15*(Inputs!$C$15*(Inputs!$C$25-AF6)+Inputs!$D$15*(Reservoir!$E$6-AF6)+Inputs!$E$15*(Inputs!$D$25-AF6))) -> 0.50783121 | AG7: =IF(AG6="","",AG6+Inputs!$B$5/Inputs!$B$15*(Inputs!$C$15*(Inputs!$C$26-AG6)+Inputs!$D$15*(Reservoir!$F$6-AG6)+Inputs!$E$15*(Inputs!$D$26-AG6))) -> 40.651871 | AH7: =IF(AH6="","",AH6+Inputs!$B$5/Inputs!$B$15*(Inputs!$C$15*(Inputs!$C$27-AH6)+Inputs!$D$15*(Reservoir!$G$6-AH6)+Inputs!$E$15*(Inputs!$D$27-AH6))) -> 30.018351 | AI7: =IF(AE7<>0,AF7/AE7,"") -> 0.62829736 | AK7: 2 | AL7: =IF(AL6="","",AL6+Inputs!$B$5/Inputs!$B$16*(Inputs!$C$16*(IF(Inputs!$C$23>0,10^(-Inputs!$C$23),0)-AL6)+Inputs!$D$16*(Reservoir!$B$6-AL6)+Inputs!$E$16*(IF(Inputs!$D$23>0,10^(-Inputs!$D$23),0)-AL6))) -> 3.2668976e-07 | AM7: =IF(AL7>0,-LOG10(AL7),"") -> 6.4858645 | AN7: =IF(AN6="","",AN6+Inputs!$B$5/Inputs!$B$16*(Inputs!$C$16*(Inputs!$C$24-AN6)+Inputs!$D$16*(Reservoir!$D$6-AN6)+Inputs!$E$16*(Inputs!$D$24-AN6))) -> 0.72856306 | AO7: =IF(AO6="","",AO6+Inputs!$B$5/Inputs!$B$16*(Inputs!$C$16*(Inputs!$C$25-AO6)+Inputs!$D$16*(Reservoir!$E$6-AO6)+Inputs!$E$16*(Inputs!$D$25-AO6))) -> 0.43454142 | AP7: =IF(AP6="","",AP6+Inputs!$B$5/Inputs!$B$16*(Inputs!$C$16*(Inputs!$C$26-AP6)+Inputs!$D$16*(Reservoir!$F$6-AP6)+Inputs!$E$16*(Inputs!$D$26-AP6))) -> 40.468647 | AQ7: =IF(AQ6="","",AQ6+Inputs!$B$5/Inputs!$B$16*(Inputs!$C$16*(Inputs!$C$27-AQ6)+Inputs!$D$16*(Reservoir!$G$6-AQ6)+Inputs!$E$16*(Inputs!$D$27-AQ6))) -> 29.56029 | AR7: =IF(AN7<>0,AO7/AN7,"") -> 0.59643624
A8: 3 | B8: =IF(B7="","",B7+Inputs!$B$5/Inputs!$B$12*(Inputs!$C$12*(IF(Inputs!$C$23>0,10^(-Inputs!$C$23),0)-B7)+Inputs!$D$12*(Reservoir!$B$7-B7)+Inputs!$E$12*(IF(Inputs!$D$23>0,10^(-Inputs!$D$23),0)-B7))) -> 3.2076274e-06 | C8: =IF(B8>0,-LOG10(B8),"") -> 5.4938161 | D8: =IF(D7="","",D7+Inputs!$B$5/Inputs!$B$12*(Inputs!$C$12*(Inputs!$C$24-D7)+Inputs!$D$12*(Reservoir!$D$7-D7)+Inputs!$E$12*(Inputs!$D$24-D7))) -> 3.2115572 | E8: =IF(E7="","",E7+Inputs!$B$5/Inputs!$B$12*(Inputs!$C$12*(Inputs!$C$25-E7)+Inputs!$D$12*(Reservoir!$E$7-E7)+Inputs!$E$12*(Inputs!$D$25-E7))) -> 0.45472692 | F8: =IF(F7="","",F7+Inputs!$B$5/Inputs!$B$12*(Inputs!$C$12*(Inputs!$C$26-F7)+Inputs!$D$12*(Reservoir!$F$7-F7)+Inputs!$E$12*(Inputs!$D$26-F7))) -> 29.407149 | G8: =IF(G7="","",G7+Inputs!$B$5/Inputs!$B$12*(Inputs!$C$12*(Inputs!$C$27-G7)+Inputs!$D$12*(Reservoir!$G$7-G7)+Inputs!$E$12*(Inputs!$D$27-G7))) -> 19.956418 | H8: =IF(D8<>0,E8/D8,"") -> 0.14159079 | J8: 3 | K8: =IF(K7="","",K7+Inputs!$B$5/Inputs!$B$13*(Inputs!$C$13*(IF(Inputs!$C$23>0,10^(-Inputs!$C$23),0)-K7)+Inputs!$D$13*(Reservoir!$B$7-K7)+Inputs!$E$13*(IF(Inputs!$D$23>0,10^(-Inputs!$D$23),0)-K7))) -> 3.2076274e-06 | L8: =IF(K8>0,-LOG10(K8),"") -> 5.4938161 | M8: =IF(M7="","",M7+Inputs!$B$5/Inputs!$B$13*(Inputs!$C$13*(Inputs!$C$24-M7)+Inputs!$D$13*(Reservoir!$D$7-M7)+Inputs!$E$13*(Inputs!$D$24-M7))) -> 3.2115572 | N8: =IF(N7="","",N7+Inputs!$B$5/Inputs!$B$13*(Inputs!$C$13*(Inputs!$C$25-N7)+Inputs!$D$13*(Reservoir!$E$7-N7)+Inputs!$E$13*(Inputs!$D$25-N7))) -> 0.45558043 | O8: =IF(O7="","",O7+Inputs!$B$5/Inputs!$B$13*(Inputs!$C$13*(Inputs!$C$26-O7)+Inputs!$D$13*(Reservoir!$F$7-O7)+Inputs!$E$13*(Inputs!$D$26-O7))) -> 28.553636 | P8: =IF(P7="","",P7+Inputs!$B$5/Inputs!$B$13*(Inputs!$C$13*(Inputs!$C$27-P7)+Inputs!$D$13*(Reservoir!$G$7-P7)+Inputs!$E$13*(Inputs!$D$27-P7))) -> 19.785715 | Q8: =IF(M8<>0,N8/M8,"") -> 0.14185655 | S8: 3 | T8: =IF(T7="","",T7+Inputs!$B$5/Inputs!$B$14*(Inputs!$C$14*(IF(Inputs!$C$23>0,10^(-Inputs!$C$23),0)-T7)+Inputs!$D$14*(Reservoir!$B$7-T7)+Inputs!$E$14*(IF(Inputs!$D$23>0,10^(-Inputs!$D$23),0)-T7))) -> 4.3797081e-06 | U8: =IF(T8>0,-LOG10(T8),"") -> 5.3585548 | V8: =IF(V7="","",V7+Inputs!$B$5/Inputs!$B$14*(Inputs!$C$14*(Inputs!$C$24-V7)+Inputs!$D$14*(Reservoir!$D$7-V7)+Inputs!$E$14*(Inputs!$D$24-V7))) -> 3.4917738 | W8: =IF(W7="","",W7+Inputs!$B$5/Inputs!$B$14*(Inputs!$C$14*(Inputs!$C$25-W7)+Inputs!$D$14*(Reservoir!$E$7-W7)+Inputs!$E$14*(Inputs!$D$25-W7))) -> 0.56763569 | X8: =IF(X7="","",X7+Inputs!$B$5/Inputs!$B$14*(Inputs!$C$14*(Inputs!$C$26-X7)+Inputs!$D$14*(Reservoir!$F$7-X7)+Inputs!$E$14*(Inputs!$D$26-X7))) -> 28.160297 | Y8: =IF(Y7="","",Y7+Inputs!$B$5/Inputs!$B$14*(Inputs!$C$14*(Inputs!$C$27-Y7)+Inputs!$D$14*(Reservoir!$G$7-Y7)+Inputs!$E$14*(Inputs!$D$27-Y7))) -> 19.625129 | Z8: =IF(V8<>0,W8/V8,"") -> 0.16256371 | AB8: 3 | AC8: =IF(AC7="","",AC7+Inputs!$B$5/Inputs!$B$15*(Inputs!$C$15*(IF(Inputs!$C$23>0,10^(-Inputs!$C$23),0)-AC7)+Inputs!$D$15*(Reservoir!$B$7-AC7)+Inputs!$E$15*(IF(Inputs!$D$23>0,10^(-Inputs!$D$23),0)-AC7))) -> 3.5785369e-07 | AD8: =IF(AC8>0,-LOG10(AC8),"") -> 6.4462945 | AE8: =IF(AE7="","",AE7+Inputs!$B$5/Inputs!$B$15*(Inputs!$C$15*(Inputs!$C$24-AE7)+Inputs!$D$15*(Reservoir!$D$7-AE7)+Inputs!$E$15*(Inputs!$D$24-AE7))) -> 0.85144049 | AF8: =IF(AF7="","",AF7+Inputs!$B$5/Inputs!$B$15*(Inputs!$C$15*(Inputs!$C$25-AF7)+Inputs!$D$15*(Reservoir!$E$7-AF7)+Inputs!$E$15*(Inputs!$D$25-AF7))) -> 0.50838329 | AG8: =IF(AG7="","",AG7+Inputs!$B$5/Inputs!$B$15*(Inputs!$C$15*(Inputs!$C$26-AG7)+Inputs!$D$15*(Reservoir!$F$7-AG7)+Inputs!$E$15*(Inputs!$D$26-AG7))) -> 40.754241 | AH8: =IF(AH7="","",AH7+Inputs!$B$5/Inputs!$B$15*(Inputs!$C$15*(Inputs!$C$27-AH7)+Inputs!$D$15*(Reservoir!$G$7-AH7)+Inputs!$E$15*(Inputs!$D$27-AH7))) -> 29.803824 | AI8: =IF(AE8<>0,AF8/AE8,"") -> 0.59708612 | AK8: 3 | AL8: =IF(AL7="","",AL7+Inputs!$B$5/Inputs!$B$16*(Inputs!$C$16*(IF(Inputs!$C$23>0,10^(-Inputs!$C$23),0)-AL7)+Inputs!$D$16*(Reservoir!$B$7-AL7)+Inputs!$E$16*(IF(Inputs!$D$23>0,10^(-Inputs!$D$23),0)-AL7))) -> 3.5785369e-07 | AM8: =IF(AL8>0,-LOG10(AL8),"") -> 6.4462945 | AN8: =IF(AN7="","",AN7+Inputs!$B$5/Inputs!$B$16*(Inputs!$C$16*(Inputs!$C$24-AN7)+Inputs!$D$16*(Reservoir!$D$7-AN7)+Inputs!$E$16*(Inputs!$D$24-AN7))) -> 0.77515366 | AO8: =IF(AO7="","",AO7+Inputs!$B$5/Inputs!$B$16*(Inputs!$C$16*(Inputs!$C$25-AO7)+Inputs!$D$16*(Reservoir!$E$7-AO7)+Inputs!$E$16*(Inputs!$D$25-AO7))) -> 0.43823449 | AP8: =IF(AP7="","",AP7+Inputs!$B$5/Inputs!$B$16*(Inputs!$C$16*(Inputs!$C$26-AP7)+Inputs!$D$16*(Reservoir!$F$7-AP7)+Inputs!$E$16*(Inputs!$D$26-AP7))) -> 40.578869 | AQ8: =IF(AQ7="","",AQ7+Inputs!$B$5/Inputs!$B$16*(Inputs!$C$16*(Inputs!$C$27-AQ7)+Inputs!$D$16*(Reservoir!$G$7-AQ7)+Inputs!$E$16*(Inputs!$D$27-AQ7))) -> 29.365394 | AR8: =IF(AN8<>0,AO8/AN8,"") -> 0.56535176
